Workbook
Name 상품종류: Data_Input!$I$2:$I$5

Sheet Data_Input
A1: 구분 | C1: 계좌번호 | E1: 납입일
A2: =I2 -> 연금저축 | H2: 상품종류 | I2: 연금저축
A3: =I3 -> IRP | C3: 204-03-53***8 | E3: 15 | I3: IRP
A4: =I4 -> 연금저축_거치 | I4: 연금저축_거치
A5: 고객명 | C5: 김명화
A7: 상품옵션 | B7: IRP | C7: IRP | D7: IRP
A8: 조회일자 | B8: 46064 | C8: 46023 | D8: 45992
A9: 월 납입액 | B9: 300000 | C9: 300000
A10: 납입원금 | B10: 80000000 | C10: 80000000
A11: 1 | B11: 플랜번호 | C11: 플랜번호 | D11: 플랜번호
A12: 2 | B12: S0124210712831 | C12: S0124210712831 | D12: S0124210712831
A13: 3 | B13: 플랜명 | C13: 플랜명 | D13: 플랜명
A14: 4 | B14: 김명화_개인IRP | C14: 김명화_개인IRP | D14: 김명화_개인IRP
A15: 5 | B15: 평가금액 | C15: 평가금액 | D15: 평가금액
A16: 6 | B16: 122628271 | C16: 117707779 | D16: 116370580
A17: 7 | B17: 평가손익 | C17: 평가손익 | D17: 평가손익
A18: 8 | B18: 26500109 | C18: 21829617 | D18: 20742418
A19: 9 | B19: 누적수익률 | C19: 누적수익률 | D19: 누적수익률
A20: 10 | B20: 46.78 | C20: 38.92 | D20: 37.24
A21: 11 | B21: 상품유형 | C21: 상품유형 | D21: 상품유형
A22: 12 | B22: 상품명 | C22: 상품명 | D22: 상품명
A23: 13 | B23: 수량 | C23: 수량 | D23: 수량
A24: 14 | B24: 기준가(이율) | C24: 기준가(이율) | D24: 기준가(이율)
A25: 15 | B25: 평가금액 | C25: 평가금액 | D25: 평가금액
A26: 16 | B26: 매입금액 | C26: 매입금액 | D26: 매입금액
A27: 17 | B27: 총 입금액 | C27: 총 입금액 | D27: 총 입금액
A28: 18 | B28: 총 출금액 | C28: 총 출금액 | D28: 총 출금액
A29: 19 | B29: 증거금액(수량) | C29: 증거금액(수량) | D29: 증거금액(수량)
A30: 20 | B30: 매수일자 | C30: 매수일자 | D30: 매수일자
A31: 21 | B31: 만기일 | C31: 만기일 | D31: 만기일
A32: 22 | B32: 수익률 | C32: 수익률 | D32: 수익률
... A34: 24 | B34: 미래에셋인도중소형포커스증권자투자신탁1호(주식)C-P2e | C34: 미래에셋인도중소형포커스증권자투자신탁1호(주식)C-P2e | D34: 미래에셋인도중소형포커스증권자투자신탁1호(주식)C-P2e
A35: 25 | B35: 1743983 | C35: 1743983 | D35: 1743983
A36: 26 | B36: 3092.24 | C36: 3107.13 | D36: 3248.72
A37: 27 | B37: 5392814 | C37: 5418782 | D37: 5665713
A38: 28 | B38: 5570000 | C38: 5570000 | D38: 5570000
A39: 29 | B39: 5570000 | C39: 5570000 | D39: 5570000
A40: 30 | B40: 0 | C40: 0 | D40: 0
A41: 31 | B41: 0 | C41: 0 | D41: 0
A42: 32 | B42: - | C42: - | D42: -
...

Sheet DB_연금저축_History
A3: DB_연금저축_HISTORY | E3: 상품종류 : | F3: 연금저축
A5: NO. | B5: 조회일 | C5: 계좌번호 | D5: 납입원금 | E5: 월 납입액 | F5: 예수금 | G5: 총자산 | H5: 매입금액 | I5: 평가금액 | J5: 평가손익 | K5: 총수익률 | L5: 상품유형 | M5: 상품명 | N5: 종목코드 | O5: 잔고수량 | P5: 매입가 | Q5: 현재가 | R5: 평가금액 | S5: 평가손익 | T5: 수익률 | U5: 만기일 | V5: 상품유형 | W5: 상품명 | X5: 종목코드 | Y5: 잔고수량 | Z5: 매입가 | AA5: 현재가 | AB5: 평가금액 | AC5: 평가손익 | AD5: 수익률 | AE5: 만기일 | AF5: 상품유형 | AG5: 상품명 | AH5: 종목코드 | AI5: 잔고수량 | AJ5: 매입가 | AK5: 현재가 | AL5: 평가금액 | AM5: 평가손익 | AN5: 수익률 | AO5: 만기일 | AP5: 상품유형 | AQ5: 상품명 | AR5: 종목코드 | AS5: 잔고수량 | AT5: 매입가 | AU5: 현재가 | AV5: 평가금액 | AW5: 평가손익 | AX5: 수익률 | AY5: 만기일 | AZ5: 상품유형 | BA5: 상품명 | BB5: 종목코드 | BC5: 잔고수량 | BD5: 매입가 | BE5: 현재가 | BF5: 평가금액 | BG5: 평가손익 | BH5: 수익률 | BI5: 만기일 | BJ5: 상품유형 | BK5: 상품명 | BL5: 종목코드 | BM5: 잔고수량 | BN5: 매입가 | BO5: 현재가 | BP5: 평가금액 | BQ5: 평가손익 | BR5: 수익률 | BS5: 만기일 | BT5: 상품유형 | BU5: 상품명 | BV5: 종목코드 | BW5: 잔고수량 | BX5: 매입가 | BY5: 현재가 | BZ5: 평가금액 | CA5: 평가손익 | CB5: 수익률 | CC5: 만기일 | CD5: 상품유형 | CE5: 상품명 | CF5: 종목코드 | CG5: 잔고수량 | CH5: 매입가 | CI5: 현재가 | CJ5: 평가금액 | CK5: 평가손익 | CL5: 수익률 | CM5: 만기일 | CN5: 상품유형 | CO5: 상품명 | CP5: 종목코드 | CQ5: 잔고수량 | CR5: 매입가 | CS5: 현재가 | CT5: 평가금액 | CU5: 평가손익 | CV5: 수익률 | CW5: 만기일 | CX5: 상품유형 | CY5: 상품명 | CZ5: 종목코드 | DA5: 잔고수량 | DB5: 매입가 | DC5: 현재가 | DD5: 평가금액 | DE5: 평가손익 | DF5: 수익률 | DG5: 만기일 | DH5: 상품유형 | DI5: 상품명 | DJ5: 종목코드 | DK5: 잔고수량 | DL5: 매입가 | DM5: 현재가 | DN5: 평가금액 | DO5: 평가손익 | DP5: 수익률 | DQ5: 만기일 | DR5: 상품유형 | DS5: 상품명 | DT5: 종목코드 | DU5: 잔고수량 | DV5: 매입가 | DW5: 현재가 | DX5: 평가금액 | DY5: 평가손익 | DZ5: 수익률 | EA5: 만기일 | EB5: 상품유형 | EC5: 상품명 | ED5: 종목코드 | EE5: 잔고수량 | EF5: 매입가 | EG5: 현재가 | EH5: 평가금액 | EI5: 평가손익 | EJ5: 수익률 | EK5: 만기일 | EL5: 상품유형 | EM5: 상품명 | EN5: 종목코드 | EO5: 잔고수량 | EP5: 매입가 | EQ5: 현재가 | ER5: 평가금액 | ES5: 평가손익 | ET5: 수익률 | EU5: 만기일 | EV5: 상품유형 | EW5: 상품명 | EX5: 종목코드 | EY5: 잔고수량 | EZ5: 매입가 | FA5: 현재가 | FB5: 평가금액 | FC5: 평가손익 | FD5: 수익률 | FE5: 만기일 | FF5: 상품유형 | FG5: 상품명 | FH5: 종목코드 | FI5: 잔고수량 | FJ5: 매입가 | FK5: 현재가 | FL5: 평가금액 | FM5: 평가손익 | FN5: 수익률 | FO5: 만기일
A6: 1 | B6: {=IFERROR(_xlfn._xlws.SORT(_xlfn.TOCOL(_xlfn.UNIQUE(_xlfn._xlws.FILTER(Data_Input!$B$8:$ZZ$8,Data_Input!$B$7:$ZZ$7=$F$3))),1,1),"")} | C6: =IF(B6>0,IF($F$3=Data_Input!$I$2,Data_Input!$C$2, IF($F$3=Data_Input!$I$3,Data_Input!$C$3,IF($F$3=Data_Input!$I$4,Data_Input!$C$4,""))),"") -> 0 | D6: {=IFERROR(INDEX(Data_Input!$10:$10,MATCH(1,(Data_Input!$7:$7=$F$3)*(Data_Input!$8:$8=$B6),0)),"")} | E6: {=IFERROR(INDEX(Data_Input!$1:$100, 9, MATCH(1, (Data_Input!$7:$7=$F$3) * (Data_Input!$8:$8=$B6), 0)),"")} | F6: {=IFERROR(INDEX(Data_Input!$A$1:$ZZ$502, MATCH("예수금", INDEX(Data_Input!$A$1:$ZZ$502, 0, MATCH(1, (Data_Input!$7:$7=$F$3)*(Data_Input!$8:$8=$B6), 0)), 0) + 1, MATCH(1, (Data_Input!$7:$7=$F$3)*(Data_Input!$8:$8=$B6), 0)),"")} | G6: {=IFERROR(INDEX(Data_Input!$A$1:$ZZ$502, MATCH("총자산", INDEX(Data_Input!$A$1:$ZZ$502, 0, MATCH(1, (Data_Input!$7:$7=$F$3)*(Data_Input!$8:$8=$B6), 0)), 0) + 1, MATCH(1, (Data_Input!$7:$7=$F$3)*(Data_Input!$8:$8=$B6), 0)),"")} | H6: {=IFERROR(INDEX(Data_Input!$A$1:$ZZ$502, MATCH("매입금액", INDEX(Data_Input!$A$1:$ZZ$502, 0, MATCH(1, (Data_Input!$7:$7=$F$3)*(Data_Input!$8:$8=$B6), 0)), 0) + 1, MATCH(1, (Data_Input!$7:$7=$F$3)*(Data_Input!$8:$8=$B6), 0)),"")} | I6: {=IFERROR(INDEX(Data_Input!$A$1:$ZZ$502, MATCH("평가금액", INDEX(Data_Input!$A$1:$ZZ$502, 0, MATCH(1, (Data_Input!$7:$7=$F$3)*(Data_Input!$8:$8=$B6), 0)), 0) + 1, MATCH(1, (Data_Input!$7:$7=$F$3)*(Data_Input!$8:$8=$B6), 0)),"")} | J6: {=IFERROR(INDEX(Data_Input!$A$1:$ZZ$502, MATCH("평가손익", INDEX(Data_Input!$A$1:$ZZ$502, 0, MATCH(1, (Data_Input!$7:$7=$F$3)*(Data_Input!$8:$8=$B6), 0)), 0) + 1, MATCH(1, (Data_Input!$7:$7=$F$3)*(Data_Input!$8:$8=$B6), 0)),"")} | K6: {=IFERROR(INDEX(Data_Input!$A$1:$ZZ$502, MATCH("총수익률", INDEX(Data_Input!$A$1:$ZZ$502, 0, MATCH(1, (Data_Input!$7:$7=$F$3)*(Data_Input!$8:$8=$B6), 0)), 0) + 1, MATCH(1, (Data_Input!$7:$7=$F$3)*(Data_Input!$8:$8=$B6), 0)),"")} | L6: {=IFERROR(_xlfn.LET( _xlpm.targetDate, B6, _xlpm.colIdx, MATCH(1, (Data_Input!$7:$7=$F$3) * (Data_Input!$8:$8=_xlpm.targetDate), 0), _xlpm.allData, INDEX(Data_Input!$1:$1002, 34, _xlpm.colIdx):INDEX(Data_Input!$1:$1002, 1000, _xlpm.colIdx), _xlpm.markedData, _xlfn.MAP(_xlfn.SEQUENCE(ROWS(_xlpm.allData)), _xlfn.LAMBDA(_xlpm.r, _xlfn.LET( _xlpm.checkRange, INDEX(_xlpm.allData, MAX(1, _xlpm.r-3)):INDEX(_xlpm.allData, _xlpm.r), _xlpm.isSubtotalInBlock, OR(_xlfn.MAP(_xlpm.checkRange, _xlfn.LAMBDA(_xlpm.v, ISNUMBER(SEARCH("소계", _xlpm.v))))), IF(_xlpm.isSubtotalInBlock, "SKIP", INDEX(_xlpm.allData, _xlpm.r)) ) )), _xlpm.validData, _xlfn._xlws.FILTER(_xlpm.markedData, (_xlpm.markedData <> "SKIP") * (_xlpm.markedData <> "")), _xlfn.TOROW(_xlpm.validData) ),"")}
A7: =IF(B7>0,A6+1,"") | C7: =IF(B7>0,C6,"") | D7: {=IFERROR(INDEX(Data_Input!$10:$10,MATCH(1,(Data_Input!$7:$7=$F$3)*(Data_Input!$8:$8=$B7),0)),"")} | E7: {=IFERROR(INDEX(Data_Input!$1:$100, 9, MATCH(1, (Data_Input!$7:$7=$F$3) * (Data_Input!$8:$8=$B7), 0)),"")} | F7: {=IFERROR(INDEX(Data_Input!$A$1:$ZZ$502, MATCH("예수금", INDEX(Data_Input!$A$1:$ZZ$502, 0, MATCH(1, (Data_Input!$7:$7=$F$3)*(Data_Input!$8:$8=$B7), 0)), 0) + 1, MATCH(1, (Data_Input!$7:$7=$F$3)*(Data_Input!$8:$8=$B7), 0)),"")} | G7: {=IFERROR(INDEX(Data_Input!$A$1:$ZZ$502, MATCH("총자산", INDEX(Data_Input!$A$1:$ZZ$502, 0, MATCH(1, (Data_Input!$7:$7=$F$3)*(Data_Input!$8:$8=$B7), 0)), 0) + 1, MATCH(1, (Data_Input!$7:$7=$F$3)*(Data_Input!$8:$8=$B7), 0)),"")} | H7: {=IFERROR(INDEX(Data_Input!$A$1:$ZZ$502, MATCH("매입금액", INDEX(Data_Input!$A$1:$ZZ$502, 0, MATCH(1, (Data_Input!$7:$7=$F$3)*(Data_Input!$8:$8=$B7), 0)), 0) + 1, MATCH(1, (Data_Input!$7:$7=$F$3)*(Data_Input!$8:$8=$B7), 0)),"")} | I7: {=IFERROR(INDEX(Data_Input!$A$1:$ZZ$502, MATCH("평가금액", INDEX(Data_Input!$A$1:$ZZ$502, 0, MATCH(1, (Data_Input!$7:$7=$F$3)*(Data_Input!$8:$8=$B7), 0)), 0) + 1, MATCH(1, (Data_Input!$7:$7=$F$3)*(Data_Input!$8:$8=$B7), 0)),"")} | J7: {=IFERROR(INDEX(Data_Input!$A$1:$ZZ$502, MATCH("평가손익", INDEX(Data_Input!$A$1:$ZZ$502, 0, MATCH(1, (Data_Input!$7:$7=$F$3)*(Data_Input!$8:$8=$B7), 0)), 0) + 1, MATCH(1, (Data_Input!$7:$7=$F$3)*(Data_Input!$8:$8=$B7), 0)),"")} | K7: {=IFERROR(INDEX(Data_Input!$A$1:$ZZ$502, MATCH("총수익률", INDEX(Data_Input!$A$1:$ZZ$502, 0, MATCH(1, (Data_Input!$7:$7=$F$3)*(Data_Input!$8:$8=$B7), 0)), 0) + 1, MATCH(1, (Data_Input!$7:$7=$F$3)*(Data_Input!$8:$8=$B7), 0)),"")} | L7: {=IFERROR(_xlfn.LET( _xlpm.targetDate, B7, _xlpm.colIdx, MATCH(1, (Data_Input!$7:$7=$F$3) * (Data_Input!$8:$8=_xlpm.targetDate), 0), _xlpm.allData, INDEX(Data_Input!$1:$1002, 34, _xlpm.colIdx):INDEX(Data_Input!$1:$1002, 1000, _xlpm.colIdx), _xlpm.markedData, _xlfn.MAP(_xlfn.SEQUENCE(ROWS(_xlpm.allData)), _xlfn.LAMBDA(_xlpm.r, _xlfn.LET( _xlpm.checkRange, INDEX(_xlpm.allData, MAX(1, _xlpm.r-3)):INDEX(_xlpm.allData, _xlpm.r), _xlpm.isSubtotalInBlock, OR(_xlfn.MAP(_xlpm.checkRange, _xlfn.LAMBDA(_xlpm.v, ISNUMBER(SEARCH("소계", _xlpm.v))))), IF(_xlpm.isSubtotalInBlock, "SKIP", INDEX(_xlpm.allData, _xlpm.r)) ) )), _xlpm.validData, _xlfn._xlws.FILTER(_xlpm.markedData, (_xlpm.markedData <> "SKIP") * (_xlpm.markedData <> "")), _xlfn.TOROW(_xlpm.validData) ),"")}
A8: =IF(B8>0,A7+1,"") | C8: =IF(B8>0,C7,"") | D8: {=IFERROR(INDEX(Data_Input!$10:$10,MATCH(1,(Data_Input!$7:$7=$F$3)*(Data_Input!$8:$8=$B8),0)),"")} | E8: {=IFERROR(INDEX(Data_Input!$1:$100, 9, MATCH(1, (Data_Input!$7:$7=$F$3) * (Data_Input!$8:$8=$B8), 0)),"")} | F8: {=IFERROR(INDEX(Data_Input!$A$1:$ZZ$502, MATCH("예수금", INDEX(Data_Input!$A$1:$ZZ$502, 0, MATCH(1, (Data_Input!$7:$7=$F$3)*(Data_Input!$8:$8=$B8), 0)), 0) + 1, MATCH(1, (Data_Input!$7:$7=$F$3)*(Data_Input!$8:$8=$B8), 0)),"")} | G8: {=IFERROR(INDEX(Data_Input!$A$1:$ZZ$502, MATCH("총자산", INDEX(Data_Input!$A$1:$ZZ$502, 0, MATCH(1, (Data_Input!$7:$7=$F$3)*(Data_Input!$8:$8=$B8), 0)), 0) + 1, MATCH(1, (Data_Input!$7:$7=$F$3)*(Data_Input!$8:$8=$B8), 0)),"")} | H8: {=IFERROR(INDEX(Data_Input!$A$1:$ZZ$502, MATCH("매입금액", INDEX(Data_Input!$A$1:$ZZ$502, 0, MATCH(1, (Data_Input!$7:$7=$F$3)*(Data_Input!$8:$8=$B8), 0)), 0) + 1, MATCH(1, (Data_Input!$7:$7=$F$3)*(Data_Input!$8:$8=$B8), 0)),"")} | I8: {=IFERROR(INDEX(Data_Input!$A$1:$ZZ$502, MATCH("평가금액", INDEX(Data_Input!$A$1:$ZZ$502, 0, MATCH(1, (Data_Input!$7:$7=$F$3)*(Data_Input!$8:$8=$B8), 0)), 0) + 1, MATCH(1, (Data_Input!$7:$7=$F$3)*(Data_Input!$8:$8=$B8), 0)),"")} | J8: {=IFERROR(INDEX(Data_Input!$A$1:$ZZ$502, MATCH("평가손익", INDEX(Data_Input!$A$1:$ZZ$502, 0, MATCH(1, (Data_Input!$7:$7=$F$3)*(Data_Input!$8:$8=$B8), 0)), 0) + 1, MATCH(1, (Data_Input!$7:$7=$F$3)*(Data_Input!$8:$8=$B8), 0)),"")} | K8: {=IFERROR(INDEX(Data_Input!$A$1:$ZZ$502, MATCH("총수익률", INDEX(Data_Input!$A$1:$ZZ$502, 0, MATCH(1, (Data_Input!$7:$7=$F$3)*(Data_Input!$8:$8=$B8), 0)), 0) + 1, MATCH(1, (Data_Input!$7:$7=$F$3)*(Data_Input!$8:$8=$B8), 0)),"")} | L8: {=IFERROR(_xlfn.LET( _xlpm.targetDate, B8, _xlpm.colIdx, MATCH(1, (Data_Input!$7:$7=$F$3) * (Data_Input!$8:$8=_xlpm.targetDate), 0), _xlpm.allData, INDEX(Data_Input!$1:$1002, 34, _xlpm.colIdx):INDEX(Data_Input!$1:$1002, 1000, _xlpm.colIdx), _xlpm.markedData, _xlfn.MAP(_xlfn.SEQUENCE(ROWS(_xlpm.allData)), _xlfn.LAMBDA(_xlpm.r, _xlfn.LET( _xlpm.checkRange, INDEX(_xlpm.allData, MAX(1, _xlpm.r-3)):INDEX(_xlpm.allData, _xlpm.r), _xlpm.isSubtotalInBlock, OR(_xlfn.MAP(_xlpm.checkRange, _xlfn.LAMBDA(_xlpm.v, ISNUMBER(SEARCH("소계", _xlpm.v))))), IF(_xlpm.isSubtotalInBlock, "SKIP", INDEX(_xlpm.allData, _xlpm.r)) ) )), _xlpm.validData, _xlfn._xlws.FILTER(_xlpm.markedData, (_xlpm.markedData <> "SKIP") * (_xlpm.markedData <> "")), _xlfn.TOROW(_xlpm.validData) ),"")}
A9: =IF(B9>0,A8+1,"") | C9: =IF(B9>0,C8,"") | D9: {=IFERROR(INDEX(Data_Input!$10:$10,MATCH(1,(Data_Input!$7:$7=$F$3)*(Data_Input!$8:$8=$B9),0)),"")} | E9: {=IFERROR(INDEX(Data_Input!$1:$100, 9, MATCH(1, (Data_Input!$7:$7=$F$3) * (Data_Input!$8:$8=$B9), 0)),"")} | F9: {=IFERROR(INDEX(Data_Input!$A$1:$ZZ$502, MATCH("예수금", INDEX(Data_Input!$A$1:$ZZ$502, 0, MATCH(1, (Data_Input!$7:$7=$F$3)*(Data_Input!$8:$8=$B9), 0)), 0) + 1, MATCH(1, (Data_Input!$7:$7=$F$3)*(Data_Input!$8:$8=$B9), 0)),"")} | G9: {=IFERROR(INDEX(Data_Input!$A$1:$ZZ$502, MATCH("총자산", INDEX(Data_Input!$A$1:$ZZ$502, 0, MATCH(1, (Data_Input!$7:$7=$F$3)*(Data_Input!$8:$8=$B9), 0)), 0) + 1, MATCH(1, (Data_Input!$7:$7=$F$3)*(Data_Input!$8:$8=$B9), 0)),"")} | H9: {=IFERROR(INDEX(Data_Input!$A$1:$ZZ$502, MATCH("매입금액", INDEX(Data_Input!$A$1:$ZZ$502, 0, MATCH(1, (Data_Input!$7:$7=$F$3)*(Data_Input!$8:$8=$B9), 0)), 0) + 1, MATCH(1, (Data_Input!$7:$7=$F$3)*(Data_Input!$8:$8=$B9), 0)),"")} | I9: {=IFERROR(INDEX(Data_Input!$A$1:$ZZ$502, MATCH("평가금액", INDEX(Data_Input!$A$1:$ZZ$502, 0, MATCH(1, (Data_Input!$7:$7=$F$3)*(Data_Input!$8:$8=$B9), 0)), 0) + 1, MATCH(1, (Data_Input!$7:$7=$F$3)*(Data_Input!$8:$8=$B9), 0)),"")} | J9: {=IFERROR(INDEX(Data_Input!$A$1:$ZZ$502, MATCH("평가손익", INDEX(Data_Input!$A$1:$ZZ$502, 0, MATCH(1, (Data_Input!$7:$7=$F$3)*(Data_Input!$8:$8=$B9), 0)), 0) + 1, MATCH(1, (Data_Input!$7:$7=$F$3)*(Data_Input!$8:$8=$B9), 0)),"")} | K9: {=IFERROR(INDEX(Data_Input!$A$1:$ZZ$502, MATCH("총수익률", INDEX(Data_Input!$A$1:$ZZ$502, 0, MATCH(1, (Data_Input!$7:$7=$F$3)*(Data_Input!$8:$8=$B9), 0)), 0) + 1, MATCH(1, (Data_Input!$7:$7=$F$3)*(Data_Input!$8:$8=$B9), 0)),"")} | L9: {=IFERROR(_xlfn.LET( _xlpm.targetDate, B9, _xlpm.colIdx, MATCH(1, (Data_Input!$7:$7=$F$3) * (Data_Input!$8:$8=_xlpm.targetDate), 0), _xlpm.allData, INDEX(Data_Input!$1:$1002, 34, _xlpm.colIdx):INDEX(Data_Input!$1:$1002, 1000, _xlpm.colIdx), _xlpm.markedData, _xlfn.MAP(_xlfn.SEQUENCE(ROWS(_xlpm.allData)), _xlfn.LAMBDA(_xlpm.r, _xlfn.LET( _xlpm.checkRange, INDEX(_xlpm.allData, MAX(1, _xlpm.r-3)):INDEX(_xlpm.allData, _xlpm.r), _xlpm.isSubtotalInBlock, OR(_xlfn.MAP(_xlpm.checkRange, _xlfn.LAMBDA(_xlpm.v, ISNUMBER(SEARCH("소계", _xlpm.v))))), IF(_xlpm.isSubtotalInBlock, "SKIP", INDEX(_xlpm.allData, _xlpm.r)) ) )), _xlpm.validData, _xlfn._xlws.FILTER(_xlpm.markedData, (_xlpm.markedData <> "SKIP") * (_xlpm.markedData <> "")), _xlfn.TOROW(_xlpm.validData) ),"")}
A10: =IF(B10>0,A9+1,"") | C10: =IF(B10>0,C9,"") | D10: {=IFERROR(INDEX(Data_Input!$10:$10,MATCH(1,(Data_Input!$7:$7=$F$3)*(Data_Input!$8:$8=$B10),0)),"")} | E10: {=IFERROR(INDEX(Data_Input!$1:$100, 9, MATCH(1, (Data_Input!$7:$7=$F$3) * (Data_Input!$8:$8=$B10), 0)),"")} | F10: {=IFERROR(INDEX(Data_Input!$A$1:$ZZ$502, MATCH("예수금", INDEX(Data_Input!$A$1:$ZZ$502, 0, MATCH(1, (Data_Input!$7:$7=$F$3)*(Data_Input!$8:$8=$B10), 0)), 0) + 1, MATCH(1, (Data_Input!$7:$7=$F$3)*(Data_Input!$8:$8=$B10), 0)),"")} | G10: {=IFERROR(INDEX(Data_Input!$A$1:$ZZ$502, MATCH("총자산", INDEX(Data_Input!$A$1:$ZZ$502, 0, MATCH(1, (Data_Input!$7:$7=$F$3)*(Data_Input!$8:$8=$B10), 0)), 0) + 1, MATCH(1, (Data_Input!$7:$7=$F$3)*(Data_Input!$8:$8=$B10), 0)),"")} | H10: {=IFERROR(INDEX(Data_Input!$A$1:$ZZ$502, MATCH("매입금액", INDEX(Data_Input!$A$1:$ZZ$502, 0, MATCH(1, (Data_Input!$7:$7=$F$3)*(Data_Input!$8:$8=$B10), 0)), 0) + 1, MATCH(1, (Data_Input!$7:$7=$F$3)*(Data_Input!$8:$8=$B10), 0)),"")} | I10: {=IFERROR(INDEX(Data_Input!$A$1:$ZZ$502, MATCH("평가금액", INDEX(Data_Input!$A$1:$ZZ$502, 0, MATCH(1, (Data_Input!$7:$7=$F$3)*(Data_Input!$8:$8=$B10), 0)), 0) + 1, MATCH(1, (Data_Input!$7:$7=$F$3)*(Data_Input!$8:$8=$B10), 0)),"")} | J10: {=IFERROR(INDEX(Data_Input!$A$1:$ZZ$502, MATCH("평가손익", INDEX(Data_Input!$A$1:$ZZ$502, 0, MATCH(1, (Data_Input!$7:$7=$F$3)*(Data_Input!$8:$8=$B10), 0)), 0) + 1, MATCH(1, (Data_Input!$7:$7=$F$3)*(Data_Input!$8:$8=$B10), 0)),"")} | K10: {=IFERROR(INDEX(Data_Input!$A$1:$ZZ$502, MATCH("총수익률", INDEX(Data_Input!$A$1:$ZZ$502, 0, MATCH(1, (Data_Input!$7:$7=$F$3)*(Data_Input!$8:$8=$B10), 0)), 0) + 1, MATCH(1, (Data_Input!$7:$7=$F$3)*(Data_Input!$8:$8=$B10), 0)),"")} | L10: {=IFERROR(_xlfn.LET( _xlpm.targetDate, B10, _xlpm.colIdx, MATCH(1, (Data_Input!$7:$7=$F$3) * (Data_Input!$8:$8=_xlpm.targetDate), 0), _xlpm.allData, INDEX(Data_Input!$1:$1002, 34, _xlpm.colIdx):INDEX(Data_Input!$1:$1002, 1000, _xlpm.colIdx), _xlpm.markedData, _xlfn.MAP(_xlfn.SEQUENCE(ROWS(_xlpm.allData)), _xlfn.LAMBDA(_xlpm.r, _xlfn.LET( _xlpm.checkRange, INDEX(_xlpm.allData, MAX(1, _xlpm.r-3)):INDEX(_xlpm.allData, _xlpm.r), _xlpm.isSubtotalInBlock, OR(_xlfn.MAP(_xlpm.checkRange, _xlfn.LAMBDA(_xlpm.v, ISNUMBER(SEARCH("소계", _xlpm.v))))), IF(_xlpm.isSubtotalInBlock, "SKIP", INDEX(_xlpm.allData, _xlpm.r)) ) )), _xlpm.validData, _xlfn._xlws.FILTER(_xlpm.markedData, (_xlpm.markedData <> "SKIP") * (_xlpm.markedData <> "")), _xlfn.TOROW(_xlpm.validData) ),"")}
A11: =IF(B11>0,A10+1,"") | C11: =IF(B11>0,C10,"") | D11: {=IFERROR(INDEX(Data_Input!$10:$10,MATCH(1,(Data_Input!$7:$7=$F$3)*(Data_Input!$8:$8=$B11),0)),"")} | E11: {=IFERROR(INDEX(Data_Input!$1:$100, 9, MATCH(1, (Data_Input!$7:$7=$F$3) * (Data_Input!$8:$8=$B11), 0)),"")} | F11: {=IFERROR(INDEX(Data_Input!$A$1:$ZZ$502, MATCH("예수금", INDEX(Data_Input!$A$1:$ZZ$502, 0, MATCH(1, (Data_Input!$7:$7=$F$3)*(Data_Input!$8:$8=$B11), 0)), 0) + 1, MATCH(1, (Data_Input!$7:$7=$F$3)*(Data_Input!$8:$8=$B11), 0)),"")} | G11: {=IFERROR(INDEX(Data_Input!$A$1:$ZZ$502, MATCH("총자산", INDEX(Data_Input!$A$1:$ZZ$502, 0, MATCH(1, (Data_Input!$7:$7=$F$3)*(Data_Input!$8:$8=$B11), 0)), 0) + 1, MATCH(1, (Data_Input!$7:$7=$F$3)*(Data_Input!$8:$8=$B11), 0)),"")} | H11: {=IFERROR(INDEX(Data_Input!$A$1:$ZZ$502, MATCH("매입금액", INDEX(Data_Input!$A$1:$ZZ$502, 0, MATCH(1, (Data_Input!$7:$7=$F$3)*(Data_Input!$8:$8=$B11), 0)), 0) + 1, MATCH(1, (Data_Input!$7:$7=$F$3)*(Data_Input!$8:$8=$B11), 0)),"")} | I11: {=IFERROR(INDEX(Data_Input!$A$1:$ZZ$502, MATCH("평가금액", INDEX(Data_Input!$A$1:$ZZ$502, 0, MATCH(1, (Data_Input!$7:$7=$F$3)*(Data_Input!$8:$8=$B11), 0)), 0) + 1, MATCH(1, (Data_Input!$7:$7=$F$3)*(Data_Input!$8:$8=$B11), 0)),"")} | J11: {=IFERROR(INDEX(Data_Input!$A$1:$ZZ$502, MATCH("평가손익", INDEX(Data_Input!$A$1:$ZZ$502, 0, MATCH(1, (Data_Input!$7:$7=$F$3)*(Data_Input!$8:$8=$B11), 0)), 0) + 1, MATCH(1, (Data_Input!$7:$7=$F$3)*(Data_Input!$8:$8=$B11), 0)),"")} | K11: {=IFERROR(INDEX(Data_Input!$A$1:$ZZ$502, MATCH("총수익률", INDEX(Data_Input!$A$1:$ZZ$502, 0, MATCH(1, (Data_Input!$7:$7=$F$3)*(Data_Input!$8:$8=$B11), 0)), 0) + 1, MATCH(1, (Data_Input!$7:$7=$F$3)*(Data_Input!$8:$8=$B11), 0)),"")} | L11: {=IFERROR(_xlfn.LET( _xlpm.targetDate, B11, _xlpm.colIdx, MATCH(1, (Data_Input!$7:$7=$F$3) * (Data_Input!$8:$8=_xlpm.targetDate), 0), _xlpm.allData, INDEX(Data_Input!$1:$1002, 34, _xlpm.colIdx):INDEX(Data_Input!$1:$1002, 1000, _xlpm.colIdx), _xlpm.markedData, _xlfn.MAP(_xlfn.SEQUENCE(ROWS(_xlpm.allData)), _xlfn.LAMBDA(_xlpm.r, _xlfn.LET( _xlpm.checkRange, INDEX(_xlpm.allData, MAX(1, _xlpm.r-3)):INDEX(_xlpm.allData, _xlpm.r), _xlpm.isSubtotalInBlock, OR(_xlfn.MAP(_xlpm.checkRange, _xlfn.LAMBDA(_xlpm.v, ISNUMBER(SEARCH("소계", _xlpm.v))))), IF(_xlpm.isSubtotalInBlock, "SKIP", INDEX(_xlpm.allData, _xlpm.r)) ) )), _xlpm.validData, _xlfn._xlws.FILTER(_xlpm.markedData, (_xlpm.markedData <> "SKIP") * (_xlpm.markedData <> "")), _xlfn.TOROW(_xlpm.validData) ),"")}
A12: =IF(B12>0,A11+1,"") | C12: =IF(B12>0,C11,"") | D12: {=IFERROR(INDEX(Data_Input!$10:$10,MATCH(1,(Data_Input!$7:$7=$F$3)*(Data_Input!$8:$8=$B12),0)),"")} | E12: {=IFERROR(INDEX(Data_Input!$1:$100, 9, MATCH(1, (Data_Input!$7:$7=$F$3) * (Data_Input!$8:$8=$B12), 0)),"")} | F12: {=IFERROR(INDEX(Data_Input!$A$1:$ZZ$502, MATCH("예수금", INDEX(Data_Input!$A$1:$ZZ$502, 0, MATCH(1, (Data_Input!$7:$7=$F$3)*(Data_Input!$8:$8=$B12), 0)), 0) + 1, MATCH(1, (Data_Input!$7:$7=$F$3)*(Data_Input!$8:$8=$B12), 0)),"")} | G12: {=IFERROR(INDEX(Data_Input!$A$1:$ZZ$502, MATCH("총자산", INDEX(Data_Input!$A$1:$ZZ$502, 0, MATCH(1, (Data_Input!$7:$7=$F$3)*(Data_Input!$8:$8=$B12), 0)), 0) + 1, MATCH(1, (Data_Input!$7:$7=$F$3)*(Data_Input!$8:$8=$B12), 0)),"")} | H12: {=IFERROR(INDEX(Data_Input!$A$1:$ZZ$502, MATCH("매입금액", INDEX(Data_Input!$A$1:$ZZ$502, 0, MATCH(1, (Data_Input!$7:$7=$F$3)*(Data_Input!$8:$8=$B12), 0)), 0) + 1, MATCH(1, (Data_Input!$7:$7=$F$3)*(Data_Input!$8:$8=$B12), 0)),"")} | I12: {=IFERROR(INDEX(Data_Input!$A$1:$ZZ$502, MATCH("평가금액", INDEX(Data_Input!$A$1:$ZZ$502, 0, MATCH(1, (Data_Input!$7:$7=$F$3)*(Data_Input!$8:$8=$B12), 0)), 0) + 1, MATCH(1, (Data_Input!$7:$7=$F$3)*(Data_Input!$8:$8=$B12), 0)),"")} | J12: {=IFERROR(INDEX(Data_Input!$A$1:$ZZ$502, MATCH("평가손익", INDEX(Data_Input!$A$1:$ZZ$502, 0, MATCH(1, (Data_Input!$7:$7=$F$3)*(Data_Input!$8:$8=$B12), 0)), 0) + 1, MATCH(1, (Data_Input!$7:$7=$F$3)*(Data_Input!$8:$8=$B12), 0)),"")} | K12: {=IFERROR(INDEX(Data_Input!$A$1:$ZZ$502, MATCH("총수익률", INDEX(Data_Input!$A$1:$ZZ$502, 0, MATCH(1, (Data_Input!$7:$7=$F$3)*(Data_Input!$8:$8=$B12), 0)), 0) + 1, MATCH(1, (Data_Input!$7:$7=$F$3)*(Data_Input!$8:$8=$B12), 0)),"")} | L12: {=IFERROR(_xlfn.LET( _xlpm.targetDate, B12, _xlpm.colIdx, MATCH(1, (Data_Input!$7:$7=$F$3) * (Data_Input!$8:$8=_xlpm.targetDate), 0), _xlpm.allData, INDEX(Data_Input!$1:$1002, 34, _xlpm.colIdx):INDEX(Data_Input!$1:$1002, 1000, _xlpm.colIdx), _xlpm.markedData, _xlfn.MAP(_xlfn.SEQUENCE(ROWS(_xlpm.allData)), _xlfn.LAMBDA(_xlpm.r, _xlfn.LET( _xlpm.checkRange, INDEX(_xlpm.allData, MAX(1, _xlpm.r-3)):INDEX(_xlpm.allData, _xlpm.r), _xlpm.isSubtotalInBlock, OR(_xlfn.MAP(_xlpm.checkRange, _xlfn.LAMBDA(_xlpm.v, ISNUMBER(SEARCH("소계", _xlpm.v))))), IF(_xlpm.isSubtotalInBlock, "SKIP", INDEX(_xlpm.allData, _xlpm.r)) ) )), _xlpm.validData, _xlfn._xlws.FILTER(_xlpm.markedData, (_xlpm.markedData <> "SKIP") * (_xlpm.markedData <> "")), _xlfn.TOROW(_xlpm.validData) ),"")}
A13: =IF(B13>0,A12+1,"") | C13: =IF(B13>0,C12,"") | D13: {=IFERROR(INDEX(Data_Input!$10:$10,MATCH(1,(Data_Input!$7:$7=$F$3)*(Data_Input!$8:$8=$B13),0)),"")} | E13: {=IFERROR(INDEX(Data_Input!$1:$100, 9, MATCH(1, (Data_Input!$7:$7=$F$3) * (Data_Input!$8:$8=$B13), 0)),"")} | F13: {=IFERROR(INDEX(Data_Input!$A$1:$ZZ$502, MATCH("예수금", INDEX(Data_Input!$A$1:$ZZ$502, 0, MATCH(1, (Data_Input!$7:$7=$F$3)*(Data_Input!$8:$8=$B13), 0)), 0) + 1, MATCH(1, (Data_Input!$7:$7=$F$3)*(Data_Input!$8:$8=$B13), 0)),"")} | G13: {=IFERROR(INDEX(Data_Input!$A$1:$ZZ$502, MATCH("총자산", INDEX(Data_Input!$A$1:$ZZ$502, 0, MATCH(1, (Data_Input!$7:$7=$F$3)*(Data_Input!$8:$8=$B13), 0)), 0) + 1, MATCH(1, (Data_Input!$7:$7=$F$3)*(Data_Input!$8:$8=$B13), 0)),"")} | H13: {=IFERROR(INDEX(Data_Input!$A$1:$ZZ$502, MATCH("매입금액", INDEX(Data_Input!$A$1:$ZZ$502, 0, MATCH(1, (Data_Input!$7:$7=$F$3)*(Data_Input!$8:$8=$B13), 0)), 0) + 1, MATCH(1, (Data_Input!$7:$7=$F$3)*(Data_Input!$8:$8=$B13), 0)),"")} | I13: {=IFERROR(INDEX(Data_Input!$A$1:$ZZ$502, MATCH("평가금액", INDEX(Data_Input!$A$1:$ZZ$502, 0, MATCH(1, (Data_Input!$7:$7=$F$3)*(Data_Input!$8:$8=$B13), 0)), 0) + 1, MATCH(1, (Data_Input!$7:$7=$F$3)*(Data_Input!$8:$8=$B13), 0)),"")} | J13: {=IFERROR(INDEX(Data_Input!$A$1:$ZZ$502, MATCH("평가손익", INDEX(Data_Input!$A$1:$ZZ$502, 0, MATCH(1, (Data_Input!$7:$7=$F$3)*(Data_Input!$8:$8=$B13), 0)), 0) + 1, MATCH(1, (Data_Input!$7:$7=$F$3)*(Data_Input!$8:$8=$B13), 0)),"")} | K13: {=IFERROR(INDEX(Data_Input!$A$1:$ZZ$502, MATCH("총수익률", INDEX(Data_Input!$A$1:$ZZ$502, 0, MATCH(1, (Data_Input!$7:$7=$F$3)*(Data_Input!$8:$8=$B13), 0)), 0) + 1, MATCH(1, (Data_Input!$7:$7=$F$3)*(Data_Input!$8:$8=$B13), 0)),"")} | L13: {=IFERROR(_xlfn.LET( _xlpm.targetDate, B13, _xlpm.colIdx, MATCH(1, (Data_Input!$7:$7=$F$3) * (Data_Input!$8:$8=_xlpm.targetDate), 0), _xlpm.allData, INDEX(Data_Input!$1:$1002, 34, _xlpm.colIdx):INDEX(Data_Input!$1:$1002, 1000, _xlpm.colIdx), _xlpm.markedData, _xlfn.MAP(_xlfn.SEQUENCE(ROWS(_xlpm.allData)), _xlfn.LAMBDA(_xlpm.r, _xlfn.LET( _xlpm.checkRange, INDEX(_xlpm.allData, MAX(1, _xlpm.r-3)):INDEX(_xlpm.allData, _xlpm.r), _xlpm.isSubtotalInBlock, OR(_xlfn.MAP(_xlpm.checkRange, _xlfn.LAMBDA(_xlpm.v, ISNUMBER(SEARCH("소계", _xlpm.v))))), IF(_xlpm.isSubtotalInBlock, "SKIP", INDEX(_xlpm.allData, _xlpm.r)) ) )), _xlpm.validData, _xlfn._xlws.FILTER(_xlpm.markedData, (_xlpm.markedData <> "SKIP") * (_xlpm.markedData <> "")), _xlfn.TOROW(_xlpm.validData) ),"")}
A14: =IF(B14>0,A13+1,"") | C14: =IF(B14>0,C13,"") | D14: {=IFERROR(INDEX(Data_Input!$10:$10,MATCH(1,(Data_Input!$7:$7=$F$3)*(Data_Input!$8:$8=$B14),0)),"")} | E14: {=IFERROR(INDEX(Data_Input!$1:$100, 9, MATCH(1, (Data_Input!$7:$7=$F$3) * (Data_Input!$8:$8=$B14), 0)),"")} | F14: {=IFERROR(INDEX(Data_Input!$A$1:$ZZ$502, MATCH("예수금", INDEX(Data_Input!$A$1:$ZZ$502, 0, MATCH(1, (Data_Input!$7:$7=$F$3)*(Data_Input!$8:$8=$B14), 0)), 0) + 1, MATCH(1, (Data_Input!$7:$7=$F$3)*(Data_Input!$8:$8=$B14), 0)),"")} | G14: {=IFERROR(INDEX(Data_Input!$A$1:$ZZ$502, MATCH("총자산", INDEX(Data_Input!$A$1:$ZZ$502, 0, MATCH(1, (Data_Input!$7:$7=$F$3)*(Data_Input!$8:$8=$B14), 0)), 0) + 1, MATCH(1, (Data_Input!$7:$7=$F$3)*(Data_Input!$8:$8=$B14), 0)),"")} | H14: {=IFERROR(INDEX(Data_Input!$A$1:$ZZ$502, MATCH("매입금액", INDEX(Data_Input!$A$1:$ZZ$502, 0, MATCH(1, (Data_Input!$7:$7=$F$3)*(Data_Input!$8:$8=$B14), 0)), 0) + 1, MATCH(1, (Data_Input!$7:$7=$F$3)*(Data_Input!$8:$8=$B14), 0)),"")} | I14: {=IFERROR(INDEX(Data_Input!$A$1:$ZZ$502, MATCH("평가금액", INDEX(Data_Input!$A$1:$ZZ$502, 0, MATCH(1, (Data_Input!$7:$7=$F$3)*(Data_Input!$8:$8=$B14), 0)), 0) + 1, MATCH(1, (Data_Input!$7:$7=$F$3)*(Data_Input!$8:$8=$B14), 0)),"")} | J14: {=IFERROR(INDEX(Data_Input!$A$1:$ZZ$502, MATCH("평가손익", INDEX(Data_Input!$A$1:$ZZ$502, 0, MATCH(1, (Data_Input!$7:$7=$F$3)*(Data_Input!$8:$8=$B14), 0)), 0) + 1, MATCH(1, (Data_Input!$7:$7=$F$3)*(Data_Input!$8:$8=$B14), 0)),"")} | K14: {=IFERROR(INDEX(Data_Input!$A$1:$ZZ$502, MATCH("총수익률", INDEX(Data_Input!$A$1:$ZZ$502, 0, MATCH(1, (Data_Input!$7:$7=$F$3)*(Data_Input!$8:$8=$B14), 0)), 0) + 1, MATCH(1, (Data_Input!$7:$7=$F$3)*(Data_Input!$8:$8=$B14), 0)),"")} | L14: {=IFERROR(_xlfn.LET( _xlpm.targetDate, B14, _xlpm.colIdx, MATCH(1, (Data_Input!$7:$7=$F$3) * (Data_Input!$8:$8=_xlpm.targetDate), 0), _xlpm.allData, INDEX(Data_Input!$1:$1002, 34, _xlpm.colIdx):INDEX(Data_Input!$1:$1002, 1000, _xlpm.colIdx), _xlpm.markedData, _xlfn.MAP(_xlfn.SEQUENCE(ROWS(_xlpm.allData)), _xlfn.LAMBDA(_xlpm.r, _xlfn.LET( _xlpm.checkRange, INDEX(_xlpm.allData, MAX(1, _xlpm.r-3)):INDEX(_xlpm.allData, _xlpm.r), _xlpm.isSubtotalInBlock, OR(_xlfn.MAP(_xlpm.checkRange, _xlfn.LAMBDA(_xlpm.v, ISNUMBER(SEARCH("소계", _xlpm.v))))), IF(_xlpm.isSubtotalInBlock, "SKIP", INDEX(_xlpm.allData, _xlpm.r)) ) )), _xlpm.validData, _xlfn._xlws.FILTER(_xlpm.markedData, (_xlpm.markedData <> "SKIP") * (_xlpm.markedData <> "")), _xlfn.TOROW(_xlpm.validData) ),"")}
A15: =IF(B15>0,A14+1,"") | C15: =IF(B15>0,C14,"") | D15: {=IFERROR(INDEX(Data_Input!$10:$10,MATCH(1,(Data_Input!$7:$7=$F$3)*(Data_Input!$8:$8=$B15),0)),"")} | E15: {=IFERROR(INDEX(Data_Input!$1:$100, 9, MATCH(1, (Data_Input!$7:$7=$F$3) * (Data_Input!$8:$8=$B15), 0)),"")} | F15: {=IFERROR(INDEX(Data_Input!$A$1:$ZZ$502, MATCH("예수금", INDEX(Data_Input!$A$1:$ZZ$502, 0, MATCH(1, (Data_Input!$7:$7=$F$3)*(Data_Input!$8:$8=$B15), 0)), 0) + 1, MATCH(1, (Data_Input!$7:$7=$F$3)*(Data_Input!$8:$8=$B15), 0)),"")} | G15: {=IFERROR(INDEX(Data_Input!$A$1:$ZZ$502, MATCH("총자산", INDEX(Data_Input!$A$1:$ZZ$502, 0, MATCH(1, (Data_Input!$7:$7=$F$3)*(Data_Input!$8:$8=$B15), 0)), 0) + 1, MATCH(1, (Data_Input!$7:$7=$F$3)*(Data_Input!$8:$8=$B15), 0)),"")} | H15: {=IFERROR(INDEX(Data_Input!$A$1:$ZZ$502, MATCH("매입금액", INDEX(Data_Input!$A$1:$ZZ$502, 0, MATCH(1, (Data_Input!$7:$7=$F$3)*(Data_Input!$8:$8=$B15), 0)), 0) + 1, MATCH(1, (Data_Input!$7:$7=$F$3)*(Data_Input!$8:$8=$B15), 0)),"")} | I15: {=IFERROR(INDEX(Data_Input!$A$1:$ZZ$502, MATCH("평가금액", INDEX(Data_Input!$A$1:$ZZ$502, 0, MATCH(1, (Data_Input!$7:$7=$F$3)*(Data_Input!$8:$8=$B15), 0)), 0) + 1, MATCH(1, (Data_Input!$7:$7=$F$3)*(Data_Input!$8:$8=$B15), 0)),"")} | J15: {=IFERROR(INDEX(Data_Input!$A$1:$ZZ$502, MATCH("평가손익", INDEX(Data_Input!$A$1:$ZZ$502, 0, MATCH(1, (Data_Input!$7:$7=$F$3)*(Data_Input!$8:$8=$B15), 0)), 0) + 1, MATCH(1, (Data_Input!$7:$7=$F$3)*(Data_Input!$8:$8=$B15), 0)),"")} | K15: {=IFERROR(INDEX(Data_Input!$A$1:$ZZ$502, MATCH("총수익률", INDEX(Data_Input!$A$1:$ZZ$502, 0, MATCH(1, (Data_Input!$7:$7=$F$3)*(Data_Input!$8:$8=$B15), 0)), 0) + 1, MATCH(1, (Data_Input!$7:$7=$F$3)*(Data_Input!$8:$8=$B15), 0)),"")} | L15: {=IFERROR(_xlfn.LET( _xlpm.targetDate, B15, _xlpm.colIdx, MATCH(1, (Data_Input!$7:$7=$F$3) * (Data_Input!$8:$8=_xlpm.targetDate), 0), _xlpm.allData, INDEX(Data_Input!$1:$1002, 34, _xlpm.colIdx):INDEX(Data_Input!$1:$1002, 1000, _xlpm.colIdx), _xlpm.markedData, _xlfn.MAP(_xlfn.SEQUENCE(ROWS(_xlpm.allData)), _xlfn.LAMBDA(_xlpm.r, _xlfn.LET( _xlpm.checkRange, INDEX(_xlpm.allData, MAX(1, _xlpm.r-3)):INDEX(_xlpm.allData, _xlpm.r), _xlpm.isSubtotalInBlock, OR(_xlfn.MAP(_xlpm.checkRange, _xlfn.LAMBDA(_xlpm.v, ISNUMBER(SEARCH("소계", _xlpm.v))))), IF(_xlpm.isSubtotalInBlock, "SKIP", INDEX(_xlpm.allData, _xlpm.r)) ) )), _xlpm.validData, _xlfn._xlws.FILTER(_xlpm.markedData, (_xlpm.markedData <> "SKIP") * (_xlpm.markedData <> "")), _xlfn.TOROW(_xlpm.validData) ),"")}
A16: =IF(B16>0,A15+1,"") | C16: =IF(B16>0,C15,"") | D16: {=IFERROR(INDEX(Data_Input!$10:$10,MATCH(1,(Data_Input!$7:$7=$F$3)*(Data_Input!$8:$8=$B16),0)),"")} | E16: {=IFERROR(INDEX(Data_Input!$1:$100, 9, MATCH(1, (Data_Input!$7:$7=$F$3) * (Data_Input!$8:$8=$B16), 0)),"")} | F16: {=IFERROR(INDEX(Data_Input!$A$1:$ZZ$502, MATCH("예수금", INDEX(Data_Input!$A$1:$ZZ$502, 0, MATCH(1, (Data_Input!$7:$7=$F$3)*(Data_Input!$8:$8=$B16), 0)), 0) + 1, MATCH(1, (Data_Input!$7:$7=$F$3)*(Data_Input!$8:$8=$B16), 0)),"")} | G16: {=IFERROR(INDEX(Data_Input!$A$1:$ZZ$502, MATCH("총자산", INDEX(Data_Input!$A$1:$ZZ$502, 0, MATCH(1, (Data_Input!$7:$7=$F$3)*(Data_Input!$8:$8=$B16), 0)), 0) + 1, MATCH(1, (Data_Input!$7:$7=$F$3)*(Data_Input!$8:$8=$B16), 0)),"")} | H16: {=IFERROR(INDEX(Data_Input!$A$1:$ZZ$502, MATCH("매입금액", INDEX(Data_Input!$A$1:$ZZ$502, 0, MATCH(1, (Data_Input!$7:$7=$F$3)*(Data_Input!$8:$8=$B16), 0)), 0) + 1, MATCH(1, (Data_Input!$7:$7=$F$3)*(Data_Input!$8:$8=$B16), 0)),"")} | I16: {=IFERROR(INDEX(Data_Input!$A$1:$ZZ$502, MATCH("평가금액", INDEX(Data_Input!$A$1:$ZZ$502, 0, MATCH(1, (Data_Input!$7:$7=$F$3)*(Data_Input!$8:$8=$B16), 0)), 0) + 1, MATCH(1, (Data_Input!$7:$7=$F$3)*(Data_Input!$8:$8=$B16), 0)),"")} | J16: {=IFERROR(INDEX(Data_Input!$A$1:$ZZ$502, MATCH("평가손익", INDEX(Data_Input!$A$1:$ZZ$502, 0, MATCH(1, (Data_Input!$7:$7=$F$3)*(Data_Input!$8:$8=$B16), 0)), 0) + 1, MATCH(1, (Data_Input!$7:$7=$F$3)*(Data_Input!$8:$8=$B16), 0)),"")} | K16: {=IFERROR(INDEX(Data_Input!$A$1:$ZZ$502, MATCH("총수익률", INDEX(Data_Input!$A$1:$ZZ$502, 0, MATCH(1, (Data_Input!$7:$7=$F$3)*(Data_Input!$8:$8=$B16), 0)), 0) + 1, MATCH(1, (Data_Input!$7:$7=$F$3)*(Data_Input!$8:$8=$B16), 0)),"")} | L16: {=IFERROR(_xlfn.LET( _xlpm.targetDate, B16, _xlpm.colIdx, MATCH(1, (Data_Input!$7:$7=$F$3) * (Data_Input!$8:$8=_xlpm.targetDate), 0), _xlpm.allData, INDEX(Data_Input!$1:$1002, 34, _xlpm.colIdx):INDEX(Data_Input!$1:$1002, 1000, _xlpm.colIdx), _xlpm.markedData, _xlfn.MAP(_xlfn.SEQUENCE(ROWS(_xlpm.allData)), _xlfn.LAMBDA(_xlpm.r, _xlfn.LET( _xlpm.checkRange, INDEX(_xlpm.allData, MAX(1, _xlpm.r-3)):INDEX(_xlpm.allData, _xlpm.r), _xlpm.isSubtotalInBlock, OR(_xlfn.MAP(_xlpm.checkRange, _xlfn.LAMBDA(_xlpm.v, ISNUMBER(SEARCH("소계", _xlpm.v))))), IF(_xlpm.isSubtotalInBlock, "SKIP", INDEX(_xlpm.allData, _xlpm.r)) ) )), _xlpm.validData, _xlfn._xlws.FILTER(_xlpm.markedData, (_xlpm.markedData <> "SKIP") * (_xlpm.markedData <> "")), _xlfn.TOROW(_xlpm.validData) ),"")}
A17: =IF(B17>0,A16+1,"") | C17: =IF(B17>0,C16,"") | D17: {=IFERROR(INDEX(Data_Input!$10:$10,MATCH(1,(Data_Input!$7:$7=$F$3)*(Data_Input!$8:$8=$B17),0)),"")} | E17: {=IFERROR(INDEX(Data_Input!$1:$100, 9, MATCH(1, (Data_Input!$7:$7=$F$3) * (Data_Input!$8:$8=$B17), 0)),"")} | F17: {=IFERROR(INDEX(Data_Input!$A$1:$ZZ$502, MATCH("예수금", INDEX(Data_Input!$A$1:$ZZ$502, 0, MATCH(1, (Data_Input!$7:$7=$F$3)*(Data_Input!$8:$8=$B17), 0)), 0) + 1, MATCH(1, (Data_Input!$7:$7=$F$3)*(Data_Input!$8:$8=$B17), 0)),"")} | G17: {=IFERROR(INDEX(Data_Input!$A$1:$ZZ$502, MATCH("총자산", INDEX(Data_Input!$A$1:$ZZ$502, 0, MATCH(1, (Data_Input!$7:$7=$F$3)*(Data_Input!$8:$8=$B17), 0)), 0) + 1, MATCH(1, (Data_Input!$7:$7=$F$3)*(Data_Input!$8:$8=$B17), 0)),"")} | H17: {=IFERROR(INDEX(Data_Input!$A$1:$ZZ$502, MATCH("매입금액", INDEX(Data_Input!$A$1:$ZZ$502, 0, MATCH(1, (Data_Input!$7:$7=$F$3)*(Data_Input!$8:$8=$B17), 0)), 0) + 1, MATCH(1, (Data_Input!$7:$7=$F$3)*(Data_Input!$8:$8=$B17), 0)),"")} | I17: {=IFERROR(INDEX(Data_Input!$A$1:$ZZ$502, MATCH("평가금액", INDEX(Data_Input!$A$1:$ZZ$502, 0, MATCH(1, (Data_Input!$7:$7=$F$3)*(Data_Input!$8:$8=$B17), 0)), 0) + 1, MATCH(1, (Data_Input!$7:$7=$F$3)*(Data_Input!$8:$8=$B17), 0)),"")} | J17: {=IFERROR(INDEX(Data_Input!$A$1:$ZZ$502, MATCH("평가손익", INDEX(Data_Input!$A$1:$ZZ$502, 0, MATCH(1, (Data_Input!$7:$7=$F$3)*(Data_Input!$8:$8=$B17), 0)), 0) + 1, MATCH(1, (Data_Input!$7:$7=$F$3)*(Data_Input!$8:$8=$B17), 0)),"")} | K17: {=IFERROR(INDEX(Data_Input!$A$1:$ZZ$502, MATCH("총수익률", INDEX(Data_Input!$A$1:$ZZ$502, 0, MATCH(1, (Data_Input!$7:$7=$F$3)*(Data_Input!$8:$8=$B17), 0)), 0) + 1, MATCH(1, (Data_Input!$7:$7=$F$3)*(Data_Input!$8:$8=$B17), 0)),"")} | L17: {=IFERROR(_xlfn.LET( _xlpm.targetDate, B17, _xlpm.colIdx, MATCH(1, (Data_Input!$7:$7=$F$3) * (Data_Input!$8:$8=_xlpm.targetDate), 0), _xlpm.allData, INDEX(Data_Input!$1:$1002, 34, _xlpm.colIdx):INDEX(Data_Input!$1:$1002, 1000, _xlpm.colIdx), _xlpm.markedData, _xlfn.MAP(_xlfn.SEQUENCE(ROWS(_xlpm.allData)), _xlfn.LAMBDA(_xlpm.r, _xlfn.LET( _xlpm.checkRange, INDEX(_xlpm.allData, MAX(1, _xlpm.r-3)):INDEX(_xlpm.allData, _xlpm.r), _xlpm.isSubtotalInBlock, OR(_xlfn.MAP(_xlpm.checkRange, _xlfn.LAMBDA(_xlpm.v, ISNUMBER(SEARCH("소계", _xlpm.v))))), IF(_xlpm.isSubtotalInBlock, "SKIP", INDEX(_xlpm.allData, _xlpm.r)) ) )), _xlpm.validData, _xlfn._xlws.FILTER(_xlpm.markedData, (_xlpm.markedData <> "SKIP") * (_xlpm.markedData <> "")), _xlfn.TOROW(_xlpm.validData) ),"")}
A18: =IF(B18>0,A17+1,"") | C18: =IF(B18>0,C17,"") | D18: {=IFERROR(INDEX(Data_Input!$10:$10,MATCH(1,(Data_Input!$7:$7=$F$3)*(Data_Input!$8:$8=$B18),0)),"")} | E18: {=IFERROR(INDEX(Data_Input!$1:$100, 9, MATCH(1, (Data_Input!$7:$7=$F$3) * (Data_Input!$8:$8=$B18), 0)),"")} | F18: {=IFERROR(INDEX(Data_Input!$A$1:$ZZ$502, MATCH("예수금", INDEX(Data_Input!$A$1:$ZZ$502, 0, MATCH(1, (Data_Input!$7:$7=$F$3)*(Data_Input!$8:$8=$B18), 0)), 0) + 1, MATCH(1, (Data_Input!$7:$7=$F$3)*(Data_Input!$8:$8=$B18), 0)),"")} | G18: {=IFERROR(INDEX(Data_Input!$A$1:$ZZ$502, MATCH("총자산", INDEX(Data_Input!$A$1:$ZZ$502, 0, MATCH(1, (Data_Input!$7:$7=$F$3)*(Data_Input!$8:$8=$B18), 0)), 0) + 1, MATCH(1, (Data_Input!$7:$7=$F$3)*(Data_Input!$8:$8=$B18), 0)),"")} | H18: {=IFERROR(INDEX(Data_Input!$A$1:$ZZ$502, MATCH("매입금액", INDEX(Data_Input!$A$1:$ZZ$502, 0, MATCH(1, (Data_Input!$7:$7=$F$3)*(Data_Input!$8:$8=$B18), 0)), 0) + 1, MATCH(1, (Data_Input!$7:$7=$F$3)*(Data_Input!$8:$8=$B18), 0)),"")} | I18: {=IFERROR(INDEX(Data_Input!$A$1:$ZZ$502, MATCH("평가금액", INDEX(Data_Input!$A$1:$ZZ$502, 0, MATCH(1, (Data_Input!$7:$7=$F$3)*(Data_Input!$8:$8=$B18), 0)), 0) + 1, MATCH(1, (Data_Input!$7:$7=$F$3)*(Data_Input!$8:$8=$B18), 0)),"")} | J18: {=IFERROR(INDEX(Data_Input!$A$1:$ZZ$502, MATCH("평가손익", INDEX(Data_Input!$A$1:$ZZ$502, 0, MATCH(1, (Data_Input!$7:$7=$F$3)*(Data_Input!$8:$8=$B18), 0)), 0) + 1, MATCH(1, (Data_Input!$7:$7=$F$3)*(Data_Input!$8:$8=$B18), 0)),"")} | K18: {=IFERROR(INDEX(Data_Input!$A$1:$ZZ$502, MATCH("총수익률", INDEX(Data_Input!$A$1:$ZZ$502, 0, MATCH(1, (Data_Input!$7:$7=$F$3)*(Data_Input!$8:$8=$B18), 0)), 0) + 1, MATCH(1, (Data_Input!$7:$7=$F$3)*(Data_Input!$8:$8=$B18), 0)),"")} | L18: {=IFERROR(_xlfn.LET( _xlpm.targetDate, B18, _xlpm.colIdx, MATCH(1, (Data_Input!$7:$7=$F$3) * (Data_Input!$8:$8=_xlpm.targetDate), 0), _xlpm.allData, INDEX(Data_Input!$1:$1002, 34, _xlpm.colIdx):INDEX(Data_Input!$1:$1002, 1000, _xlpm.colIdx), _xlpm.markedData, _xlfn.MAP(_xlfn.SEQUENCE(ROWS(_xlpm.allData)), _xlfn.LAMBDA(_xlpm.r, _xlfn.LET( _xlpm.checkRange, INDEX(_xlpm.allData, MAX(1, _xlpm.r-3)):INDEX(_xlpm.allData, _xlpm.r), _xlpm.isSubtotalInBlock, OR(_xlfn.MAP(_xlpm.checkRange, _xlfn.LAMBDA(_xlpm.v, ISNUMBER(SEARCH("소계", _xlpm.v))))), IF(_xlpm.isSubtotalInBlock, "SKIP", INDEX(_xlpm.allData, _xlpm.r)) ) )), _xlpm.validData, _xlfn._xlws.FILTER(_xlpm.markedData, (_xlpm.markedData <> "SKIP") * (_xlpm.markedData <> "")), _xlfn.TOROW(_xlpm.validData) ),"")}
... A399: =IF(B399>0,A398+1,"") | C399: =IF(B399>0,C398,"") | D399: {=IFERROR(INDEX(Data_Input!$10:$10,MATCH(1,(Data_Input!$7:$7=$F$3)*(Data_Input!$8:$8=$B399),0)),"")} | E399: {=IFERROR(INDEX(Data_Input!$1:$100, 9, MATCH(1, (Data_Input!$7:$7=$F$3) * (Data_Input!$8:$8=$B399), 0)),"")} | F399: {=IFERROR(INDEX(Data_Input!$A$1:$ZZ$502, MATCH("예수금", INDEX(Data_Input!$A$1:$ZZ$502, 0, MATCH(1, (Data_Input!$7:$7=$F$3)*(Data_Input!$8:$8=$B399), 0)), 0) + 1, MATCH(1, (Data_Input!$7:$7=$F$3)*(Data_Input!$8:$8=$B399), 0)),"")} | G399: {=IFERROR(INDEX(Data_Input!$A$1:$ZZ$502, MATCH("총자산", INDEX(Data_Input!$A$1:$ZZ$502, 0, MATCH(1, (Data_Input!$7:$7=$F$3)*(Data_Input!$8:$8=$B399), 0)), 0) + 1, MATCH(1, (Data_Input!$7:$7=$F$3)*(Data_Input!$8:$8=$B399), 0)),"")} | H399: {=IFERROR(INDEX(Data_Input!$A$1:$ZZ$502, MATCH("매입금액", INDEX(Data_Input!$A$1:$ZZ$502, 0, MATCH(1, (Data_Input!$7:$7=$F$3)*(Data_Input!$8:$8=$B399), 0)), 0) + 1, MATCH(1, (Data_Input!$7:$7=$F$3)*(Data_Input!$8:$8=$B399), 0)),"")} | I399: {=IFERROR(INDEX(Data_Input!$A$1:$ZZ$502, MATCH("평가금액", INDEX(Data_Input!$A$1:$ZZ$502, 0, MATCH(1, (Data_Input!$7:$7=$F$3)*(Data_Input!$8:$8=$B399), 0)), 0) + 1, MATCH(1, (Data_Input!$7:$7=$F$3)*(Data_Input!$8:$8=$B399), 0)),"")} | J399: {=IFERROR(INDEX(Data_Input!$A$1:$ZZ$502, MATCH("평가손익", INDEX(Data_Input!$A$1:$ZZ$502, 0, MATCH(1, (Data_Input!$7:$7=$F$3)*(Data_Input!$8:$8=$B399), 0)), 0) + 1, MATCH(1, (Data_Input!$7:$7=$F$3)*(Data_Input!$8:$8=$B399), 0)),"")} | K399: {=IFERROR(INDEX(Data_Input!$A$1:$ZZ$502, MATCH("총수익률", INDEX(Data_Input!$A$1:$ZZ$502, 0, MATCH(1, (Data_Input!$7:$7=$F$3)*(Data_Input!$8:$8=$B399), 0)), 0) + 1, MATCH(1, (Data_Input!$7:$7=$F$3)*(Data_Input!$8:$8=$B399), 0)),"")} | L399: {=IFERROR(_xlfn.LET( _xlpm.targetDate, B399, _xlpm.colIdx, MATCH(1, (Data_Input!$7:$7=$F$3) * (Data_Input!$8:$8=_xlpm.targetDate), 0), _xlpm.allData, INDEX(Data_Input!$1:$1002, 34, _xlpm.colIdx):INDEX(Data_Input!$1:$1002, 1000, _xlpm.colIdx), _xlpm.markedData, _xlfn.MAP(_xlfn.SEQUENCE(ROWS(_xlpm.allData)), _xlfn.LAMBDA(_xlpm.r, _xlfn.LET( _xlpm.checkRange, INDEX(_xlpm.allData, MAX(1, _xlpm.r-3)):INDEX(_xlpm.allData, _xlpm.r), _xlpm.isSubtotalInBlock, OR(_xlfn.MAP(_xlpm.checkRange, _xlfn.LAMBDA(_xlpm.v, ISNUMBER(SEARCH("소계", _xlpm.v))))), IF(_xlpm.isSubtotalInBlock, "SKIP", INDEX(_xlpm.allData, _xlpm.r)) ) )), _xlpm.validData, _xlfn._xlws.FILTER(_xlpm.markedData, (_xlpm.markedData <> "SKIP") * (_xlpm.markedData <> "")), _xlfn.TOROW(_xlpm.validData) ),"")}

Sheet DB_IRP_History
A3: DB_IRP_HISTORY | E3: 상품종류 : | F3: IRP
A5: NO. | B5: 조회일 | C5: 계좌번호 | D5: 납입원금 | E5: 월납입액 | F5: 플랜번호 | G5: 플랜명 | H5: 평가금액 | I5: 평가손익 | J5: 누적수익률 | K5: 상품유형 | L5: 상품명 | M5: 수량 | N5: 기준가(이율) | O5: 평가금액 | P5: 매입금액 | Q5: 총입금액 | R5: 총출금액 | S5: 증거금액(수량) | T5: 매수일자 | U5: 만기일 | V5: 수익률 | W5: 상품유형 | X5: 상품명 | Y5: 수량 | Z5: 기준가(이율) | AA5: 평가금액 | AB5: 매입금액 | AC5: 총입금액 | AD5: 총출금액 | AE5: 증거금액(수량) | AF5: 매수일자 | AG5: 만기일 | AH5: 수익률 | AI5: 상품유형 | AJ5: 상품명 | AK5: 수량 | AL5: 기준가(이율) | AM5: 평가금액 | AN5: 매입금액 | AO5: 총입금액 | AP5: 총출금액 | AQ5: 증거금액(수량) | AR5: 매수일자 | AS5: 만기일 | AT5: 수익률 | AU5: 상품유형 | AV5: 상품명 | AW5: 수량 | AX5: 기준가(이율) | AY5: 평가금액 | AZ5: 매입금액 | BA5: 총입금액 | BB5: 총출금액 | BC5: 증거금액(수량) | BD5: 매수일자 | BE5: 만기일 | BF5: 수익률 | BG5: 상품유형 | BH5: 상품명 | BI5: 수량 | BJ5: 기준가(이율) | BK5: 평가금액 | BL5: 매입금액 | BM5: 총입금액 | BN5: 총출금액 | BO5: 증거금액(수량) | BP5: 매수일자 | BQ5: 만기일 | BR5: 수익률 | BS5: 상품유형 | BT5: 상품명 | BU5: 수량 | BV5: 기준가(이율) | BW5: 평가금액 | BX5: 매입금액 | BY5: 총입금액 | BZ5: 총출금액 | CA5: 증거금액(수량) | CB5: 매수일자 | CC5: 만기일 | CD5: 수익률 | CE5: 상품유형 | CF5: 상품명 | CG5: 수량 | CH5: 기준가(이율) | CI5: 평가금액 | CJ5: 매입금액 | CK5: 총입금액 | CL5: 총출금액 | CM5: 증거금액(수량) | CN5: 매수일자 | CO5: 만기일 | CP5: 수익률 | CQ5: 상품유형 | CR5: 상품명 | CS5: 수량 | CT5: 기준가(이율) | CU5: 평가금액 | CV5: 매입금액 | CW5: 총입금액 | CX5: 총출금액 | CY5: 증거금액(수량) | CZ5: 매수일자 | DA5: 만기일 | DB5: 수익률 | DC5: 상품유형 | DD5: 상품명 | DE5: 수량 | DF5: 기준가(이율) | DG5: 평가금액 | DH5: 매입금액 | DI5: 총입금액 | DJ5: 총출금액 | DK5: 증거금액(수량) | DL5: 매수일자 | DM5: 만기일 | DN5: 수익률 | DO5: 상품유형 | DP5: 상품명 | DQ5: 수량 | DR5: 기준가(이율) | DS5: 평가금액 | DT5: 매입금액 | DU5: 총입금액 | DV5: 총출금액 | DW5: 증거금액(수량) | DX5: 매수일자 | DY5: 만기일 | DZ5: 수익률 | EA5: 상품유형 | EB5: 상품명 | EC5: 수량 | ED5: 기준가(이율) | EE5: 평가금액 | EF5: 매입금액 | EG5: 총입금액 | EH5: 총출금액 | EI5: 증거금액(수량) | EJ5: 매수일자 | EK5: 만기일 | EL5: 수익률 | EM5: 상품유형 | EN5: 상품명 | EO5: 수량 | EP5: 기준가(이율) | EQ5: 평가금액 | ER5: 매입금액 | ES5: 총입금액 | ET5: 총출금액 | EU5: 증거금액(수량) | EV5: 매수일자 | EW5: 만기일 | EX5: 수익률 | EY5: 상품유형 | EZ5: 상품명 | FA5: 수량 | FB5: 기준가(이율) | FC5: 평가금액 | FD5: 매입금액 | FE5: 총입금액 | FF5: 총출금액 | FG5: 증거금액(수량) | FH5: 매수일자 | FI5: 만기일 | FJ5: 수익률 | FK5: 상품유형 | FL5: 상품명 | FM5: 수량 | FN5: 기준가(이율) | FO5: 평가금액 | FP5: 매입금액 | FQ5: 총입금액 | FR5: 총출금액 | FS5: 증거금액(수량) | FT5: 매수일자 | FU5: 만기일 | FV5: 수익률 | FW5: 상품유형 | FX5: 상품명 | FY5: 수량 | FZ5: 기준가(이율) | GA5: 평가금액 | GB5: 매입금액 | GC5: 총입금액 | GD5: 총출금액 | GE5: 증거금액(수량) | GF5: 매수일자 | GG5: 만기일 | GH5: 수익률 | GI5: 상품유형 | GJ5: 상품명 | GK5: 수량 | GL5: 기준가(이율) | GM5: 평가금액 | GN5: 매입금액 | GO5: 총입금액 | GP5: 총출금액 | GQ5: 증거금액(수량) | GR5: 매수일자 | GS5: 만기일 | GT5: 수익률 | GU5: 상품유형 | GV5: 상품명 | GW5: 수량 | GX5: 기준가(이율) | GY5: 평가금액 | GZ5: 매입금액 | HA5: 총입금액 | HB5: 총출금액 | HC5: 증거금액(수량) | HD5: 매수일자 | HE5: 만기일 | HF5: 수익률 | HG5: 상품유형 | HH5: 상품명 | HI5: 수량 | HJ5: 기준가(이율) | HK5: 평가금액 | HL5: 매입금액 | HM5: 총입금액 | HN5: 총출금액 | HO5: 증거금액(수량) | HP5: 매수일자 | HQ5: 만기일 | HR5: 수익률 | HS5: 상품유형 | HT5: 상품명 | HU5: 수량 | HV5: 기준가(이율) | HW5: 평가금액 | HX5: 매입금액 | HY5: 총입금액 | HZ5: 총출금액 | IA5: 증거금액(수량) | IB5: 매수일자 | IC5: 만기일 | ID5: 수익률 | IE5: 상품유형 | IF5: 상품명 | IG5: 수량 | IH5: 기준가(이율) | II5: 평가금액 | IJ5: 매입금액 | IK5: 총입금액 | IL5: 총출금액 | IM5: 증거금액(수량) | IN5: 매수일자 | IO5: 만기일 | IP5: 수익률
A6: 1 | B6: {=IFERROR(_xlfn._xlws.SORT(_xlfn.TOCOL(_xlfn.UNIQUE(_xlfn._xlws.FILTER(Data_Input!$B$8:$ZZ$8,Data_Input!$B$7:$ZZ$7=$F$3))),1,1),"")} -> 45992 | C6: =IF(B6>0,IF($F$3=Data_Input!$I$2,Data_Input!$C$2, IF($F$3=Data_Input!$I$3,Data_Input!$C$3,IF($F$3=Data_Input!$I$4,Data_Input!$C$4,""))),"") -> 204-03-53***8 | D6: {=IFERROR(INDEX(Data_Input!$1:$100, 10, MATCH(1, (Data_Input!$7:$7=$F$3) * (Data_Input!$8:$8=$B6), 0)), "")} -> 0 | E6: {=IFERROR(INDEX(Data_Input!$1:$100, 9, MATCH(1, (Data_Input!$7:$7=$F$3) * (Data_Input!$8:$8=$B6), 0)),"")} -> 0 | F6: {=IFERROR(INDEX(Data_Input!$A$1:$ZZ$502, MATCH("플랜번호", INDEX(Data_Input!$A$1:$ZZ$502, 0, MATCH(1, (Data_Input!$7:$7="IRP")*(Data_Input!$8:$8=$B6), 0)), 0) + 1, MATCH(1, (Data_Input!$7:$7=$F$3)*(Data_Input!$8:$8=$B6), 0)),"")} -> S0124210712831 | G6: {=IFERROR(INDEX(Data_Input!$A$1:$ZZ$502, MATCH("플랜명", INDEX(Data_Input!$A$1:$ZZ$502, 0, MATCH(1, (Data_Input!$7:$7="IRP")*(Data_Input!$8:$8=$B6), 0)), 0) + 1, MATCH(1, (Data_Input!$7:$7=$F$3)*(Data_Input!$8:$8=$B6), 0)),"")} -> 김명화_개인IRP | H6: {=IFERROR(INDEX(Data_Input!$A$1:$ZZ$502, MATCH("평가금액", INDEX(Data_Input!$A$1:$ZZ$502, 0, MATCH(1, (Data_Input!$7:$7="IRP")*(Data_Input!$8:$8=$B6), 0)), 0) + 1, MATCH(1, (Data_Input!$7:$7=$F$3)*(Data_Input!$8:$8=$B6), 0)),"")} -> 116370580 | I6: {=IFERROR(INDEX(Data_Input!$A$1:$ZZ$502, MATCH("평가손익", INDEX(Data_Input!$A$1:$ZZ$502, 0, MATCH(1, (Data_Input!$7:$7="IRP")*(Data_Input!$8:$8=$B6), 0)), 0) + 1, MATCH(1, (Data_Input!$7:$7=$F$3)*(Data_Input!$8:$8=$B6), 0)),"")} -> 20742418 | J6: {=IFERROR(INDEX(Data_Input!$A$1:$ZZ$502, MATCH("누적수익률", INDEX(Data_Input!$A$1:$ZZ$502, 0, MATCH(1, (Data_Input!$7:$7="IRP")*(Data_Input!$8:$8=$B6), 0)), 0) + 1, MATCH(1, (Data_Input!$7:$7=$F$3)*(Data_Input!$8:$8=$B6), 0))/100,"")} -> 0.3724 | K6: {=IFERROR(_xlfn.LET( _xlpm.targetDate, B6, _xlpm.colIdx, MATCH(1, (Data_Input!$7:$7=$F$3) * (Data_Input!$8:$8=_xlpm.targetDate), 0), _xlpm.allData, INDEX(Data_Input!$1:$1002, 33, _xlpm.colIdx):INDEX(Data_Input!$1:$1002, 1000, _xlpm.colIdx), _xlpm.validData, _xlfn._xlws.FILTER(_xlpm.allData, _xlpm.allData <> ""), _xlpm.finalData, _xlfn.MAP(_xlfn.SEQUENCE(ROWS(_xlpm.validData)), _xlfn.LAMBDA(_xlpm.r, _xlfn.LET( _xlpm.curr, INDEX(_xlpm.validData, _xlpm.r), _xlpm.next, IF(_xlpm.r=ROWS(_xlpm.validData), "END", INDEX(_xlpm.validData, _xlpm.r+1)), IF(AND(ISNUMBER(_xlpm.curr), ISTEXT(_xlpm.next)), _xlpm.curr/100, _xlpm.curr) ) )), _xlfn.TOROW(_xlpm.finalData) ),"")} -> 수익증권 | L6: 미래에셋인도중소형포커스증권자투자신탁1호(주식)C-P2e | M6: 1743983 | N6: 3248.72 | O6: 5665713 | P6: 5570000 | Q6: 5570000 | R6: 0 | S6: 0 | T6: - | U6: - | V6: 0.01718 | W6: 수익증권 | X6: 마이다스책임투자증권투자신탁(주식)C-Pe2 | Y6: 7627192 | Z6: 2471.58 | AA6: 18851220 | AB6: 11110352 | AC6: 13051372 | AD6: 2981193 | AE6: 0 | AF6: - | AG6: - | AH6: 0.69673 | AI6: 수익증권 | AJ6: AB미국그로스증권투자신탁(주식-재간접형)Ce-P2 | AK6: 7852261 | AL6: 2942.86 | AM6: 23108108 | AN6: 18090735 | AO6: 36715755 | AP6: 20189462 | AQ6: 0 | AR6: - | AS6: - | AT6: 0.27734 | AU6: 수익증권 | AV6: 한국투자연금베트남증권자투자신탁(주식혼합)C-Re | AW6: 8790361 | AX6: 1179.35 | AY6: 10366913 | AZ6: 10250000 | BA6: 10250000 | BB6: 0 | BC6: 0 | BD6: - | BE6: - | BF6: 0.01141 | BG6: 수익증권 | BH6: 우리하이플러스채권증권자투자신탁1호(채권)C-Pe | BI6: 14191487 | BJ6: 1040.3 | BK6: 14763406 | BL6: 12860000 | BM6: 13385000 | BN6: 525814 | BO6: 0 | BP6: - | BQ6: - | BR6: 0.14801 | BS6: 수익증권 | BT6: 한국투자글로벌AI&반도체TOP10증권자투자신탁UH(주식)C-Re | BU6: 7932805 | BV6: 2837.16 | BW6: 22506638 | BX6: 22780000 | BY6: 22780000 | BZ6: 0 | CA6: 0 | CB6: - | CC6: - | CD6: -0.012 | CE6: ETF | CF6: ACE 미국30년국채액티브(H) | CG6: 1410 | CH6: 7850 | CI6: 11068500 | CJ6: 11611350 | CK6: 0 | CL6: 0 | CM6: 0 | CN6: - | CO6: - | CP6: -0.04675 | CQ6: 현금성자산(원화) | CR6: 자동운용상품(고유계정대) | CS6: 0 | CT6: 0 | CU6: 10040082 | CV6: 10040082 | CW6: 0 | CX6: 0 | CY6: 0 | CZ6: - | DA6: - | DB6: 0
A7: =IF(B7>0,A6+1,"") -> 2 | B7: 46023 | C7: =IF(B7>0,C6,"") -> 204-03-53***8 | D7: {=IFERROR(INDEX(Data_Input!$1:$100, 10, MATCH(1, (Data_Input!$7:$7=$F$3) * (Data_Input!$8:$8=$B7), 0)), "")} -> 80000000 | E7: {=IFERROR(INDEX(Data_Input!$1:$100, 9, MATCH(1, (Data_Input!$7:$7=$F$3) * (Data_Input!$8:$8=$B7), 0)),"")} -> 300000 | F7: {=IFERROR(INDEX(Data_Input!$A$1:$ZZ$502, MATCH("플랜번호", INDEX(Data_Input!$A$1:$ZZ$502, 0, MATCH(1, (Data_Input!$7:$7="IRP")*(Data_Input!$8:$8=$B7), 0)), 0) + 1, MATCH(1, (Data_Input!$7:$7=$F$3)*(Data_Input!$8:$8=$B7), 0)),"")} -> S0124210712831 | G7: {=IFERROR(INDEX(Data_Input!$A$1:$ZZ$502, MATCH("플랜명", INDEX(Data_Input!$A$1:$ZZ$502, 0, MATCH(1, (Data_Input!$7:$7="IRP")*(Data_Input!$8:$8=$B7), 0)), 0) + 1, MATCH(1, (Data_Input!$7:$7=$F$3)*(Data_Input!$8:$8=$B7), 0)),"")} -> 김명화_개인IRP | H7: {=IFERROR(INDEX(Data_Input!$A$1:$ZZ$502, MATCH("평가금액", INDEX(Data_Input!$A$1:$ZZ$502, 0, MATCH(1, (Data_Input!$7:$7="IRP")*(Data_Input!$8:$8=$B7), 0)), 0) + 1, MATCH(1, (Data_Input!$7:$7=$F$3)*(Data_Input!$8:$8=$B7), 0)),"")} -> 117707779 | I7: {=IFERROR(INDEX(Data_Input!$A$1:$ZZ$502, MATCH("평가손익", INDEX(Data_Input!$A$1:$ZZ$502, 0, MATCH(1, (Data_Input!$7:$7="IRP")*(Data_Input!$8:$8=$B7), 0)), 0) + 1, MATCH(1, (Data_Input!$7:$7=$F$3)*(Data_Input!$8:$8=$B7), 0)),"")} -> 21829617 | J7: {=IFERROR(INDEX(Data_Input!$A$1:$ZZ$502, MATCH("누적수익률", INDEX(Data_Input!$A$1:$ZZ$502, 0, MATCH(1, (Data_Input!$7:$7="IRP")*(Data_Input!$8:$8=$B7), 0)), 0) + 1, MATCH(1, (Data_Input!$7:$7=$F$3)*(Data_Input!$8:$8=$B7), 0))/100,"")} -> 0.3892 | K7: {=IFERROR(_xlfn.LET( _xlpm.targetDate, B7, _xlpm.colIdx, MATCH(1, (Data_Input!$7:$7=$F$3) * (Data_Input!$8:$8=_xlpm.targetDate), 0), _xlpm.allData, INDEX(Data_Input!$1:$1002, 33, _xlpm.colIdx):INDEX(Data_Input!$1:$1002, 1000, _xlpm.colIdx), _xlpm.validData, _xlfn._xlws.FILTER(_xlpm.allData, _xlpm.allData <> ""), _xlpm.finalData, _xlfn.MAP(_xlfn.SEQUENCE(ROWS(_xlpm.validData)), _xlfn.LAMBDA(_xlpm.r, _xlfn.LET( _xlpm.curr, INDEX(_xlpm.validData, _xlpm.r), _xlpm.next, IF(_xlpm.r=ROWS(_xlpm.validData), "END", INDEX(_xlpm.validData, _xlpm.r+1)), IF(AND(ISNUMBER(_xlpm.curr), ISTEXT(_xlpm.next)), _xlpm.curr/100, _xlpm.curr) ) )), _xlfn.TOROW(_xlpm.finalData) ),"")} -> 수익증권 | L7: 미래에셋인도중소형포커스증권자투자신탁1호(주식)C-P2e | M7: 1743983 | N7: 3107.13 | O7: 5418782 | P7: 5570000 | Q7: 5570000 | R7: 0 | S7: 0 | T7: - | U7: - | V7: -0.02715 | W7: 수익증권 | X7: 마이다스책임투자증권투자신탁(주식)C-Pe2 | Y7: 7627192 | Z7: 2649.32 | AA7: 20206876 | AB7: 11110352 | AC7: 13051372 | AD7: 2981193 | AE7: 0 | AF7: - | AG7: - | AH7: 0.81874 | AI7: 수익증권 | AJ7: AB미국그로스증권투자신탁(주식-재간접형)Ce-P2 | AK7: 7852261 | AL7: 2932.42 | AM7: 23026130 | AN7: 18090735 | AO7: 36715755 | AP7: 20189462 | AQ7: 0 | AR7: - | AS7: - | AT7: 0.27281 | AU7: 수익증권 | AV7: 한국투자연금베트남증권자투자신탁(주식혼합)C-Re | AW7: 10546825 | AX7: 1016.58 | AY7: 10721693 | AZ7: 10250000 | BA7: 10250000 | BB7: 0 | BC7: 0 | BD7: - | BE7: - | BF7: 0.04602 | BG7: 수익증권 | BH7: 우리하이플러스채권증권자투자신탁1호(채권)C-Pe | BI7: 14191487 | BJ7: 1043.73 | BK7: 14812084 | BL7: 12860000 | BM7: 13385000 | BN7: 525814 | BO7: 0 | BP7: - | BQ7: - | BR7: 0.1518 | BS7: 수익증권 | BT7: 한국투자글로벌AI&반도체TOP10증권자투자신탁UH(주식)C-Re | BU7: 7932805 | BV7: 2817.08 | BW7: 22347347 | BX7: 22780000 | BY7: 22780000 | BZ7: 0 | CA7: 0 | CB7: - | CC7: - | CD7: -0.01899 | CE7: ETF | CF7: ACE 미국30년국채액티브(H) | CG7: 1410 | CH7: 7680 | CI7: 10828800 | CJ7: 11611350 | CK7: 0 | CL7: 0 | CM7: 0 | CN7: - | CO7: - | CP7: -0.0674 | CQ7: 현금성자산(원화) | CR7: 자동운용상품(고유계정대) | CS7: 0 | CT7: 0 | CU7: 10346067 | CV7: 10346067 | CW7: 0 | CX7: 0 | CY7: 0 | CZ7: - | DA7: - | DB7: 0
A8: =IF(B8>0,A7+1,"") -> 3 | B8: 46064 | C8: =IF(B8>0,C7,"") -> 204-03-53***8 | D8: {=IFERROR(INDEX(Data_Input!$1:$100, 10, MATCH(1, (Data_Input!$7:$7=$F$3) * (Data_Input!$8:$8=$B8), 0)), "")} -> 80000000 | E8: {=IFERROR(INDEX(Data_Input!$1:$100, 9, MATCH(1, (Data_Input!$7:$7=$F$3) * (Data_Input!$8:$8=$B8), 0)),"")} -> 300000 | F8: {=IFERROR(INDEX(Data_Input!$A$1:$ZZ$502, MATCH("플랜번호", INDEX(Data_Input!$A$1:$ZZ$502, 0, MATCH(1, (Data_Input!$7:$7="IRP")*(Data_Input!$8:$8=$B8), 0)), 0) + 1, MATCH(1, (Data_Input!$7:$7=$F$3)*(Data_Input!$8:$8=$B8), 0)),"")} -> S0124210712831 | G8: {=IFERROR(INDEX(Data_Input!$A$1:$ZZ$502, MATCH("플랜명", INDEX(Data_Input!$A$1:$ZZ$502, 0, MATCH(1, (Data_Input!$7:$7="IRP")*(Data_Input!$8:$8=$B8), 0)), 0) + 1, MATCH(1, (Data_Input!$7:$7=$F$3)*(Data_Input!$8:$8=$B8), 0)),"")} -> 김명화_개인IRP | H8: {=IFERROR(INDEX(Data_Input!$A$1:$ZZ$502, MATCH("평가금액", INDEX(Data_Input!$A$1:$ZZ$502, 0, MATCH(1, (Data_Input!$7:$7="IRP")*(Data_Input!$8:$8=$B8), 0)), 0) + 1, MATCH(1, (Data_Input!$7:$7=$F$3)*(Data_Input!$8:$8=$B8), 0)),"")} -> 122628271 | I8: {=IFERROR(INDEX(Data_Input!$A$1:$ZZ$502, MATCH("평가손익", INDEX(Data_Input!$A$1:$ZZ$502, 0, MATCH(1, (Data_Input!$7:$7="IRP")*(Data_Input!$8:$8=$B8), 0)), 0) + 1, MATCH(1, (Data_Input!$7:$7=$F$3)*(Data_Input!$8:$8=$B8), 0)),"")} -> 26500109 | J8: {=IFERROR(INDEX(Data_Input!$A$1:$ZZ$502, MATCH("누적수익률", INDEX(Data_Input!$A$1:$ZZ$502, 0, MATCH(1, (Data_Input!$7:$7="IRP")*(Data_Input!$8:$8=$B8), 0)), 0) + 1, MATCH(1, (Data_Input!$7:$7=$F$3)*(Data_Input!$8:$8=$B8), 0))/100,"")} -> 0.4678 | K8: {=IFERROR(_xlfn.LET( _xlpm.targetDate, B8, _xlpm.colIdx, MATCH(1, (Data_Input!$7:$7=$F$3) * (Data_Input!$8:$8=_xlpm.targetDate), 0), _xlpm.allData, INDEX(Data_Input!$1:$1002, 33, _xlpm.colIdx):INDEX(Data_Input!$1:$1002, 1000, _xlpm.colIdx), _xlpm.validData, _xlfn._xlws.FILTER(_xlpm.allData, _xlpm.allData <> ""), _xlpm.finalData, _xlfn.MAP(_xlfn.SEQUENCE(ROWS(_xlpm.validData)), _xlfn.LAMBDA(_xlpm.r, _xlfn.LET( _xlpm.curr, INDEX(_xlpm.validData, _xlpm.r), _xlpm.next, IF(_xlpm.r=ROWS(_xlpm.validData), "END", INDEX(_xlpm.validData, _xlpm.r+1)), IF(AND(ISNUMBER(_xlpm.curr), ISTEXT(_xlpm.next)), _xlpm.curr/100, _xlpm.curr) ) )), _xlfn.TOROW(_xlpm.finalData) ),"")} -> 수익증권 | L8: 미래에셋인도중소형포커스증권자투자신탁1호(주식)C-P2e | M8: 1743983 | N8: 3092.24 | O8: 5392814 | P8: 5570000 | Q8: 5570000 | R8: 0 | S8: 0 | T8: - | U8: - | V8: -0.03181 | W8: 수익증권 | X8: 마이다스책임투자증권투자신탁(주식)C-Pe2 | Y8: 4017661 | Z8: 3290.15 | AA8: 13218710 | AB8: 5647761 | AC8: 13051372 | AD8: 14041194 | AE8: 0 | AF8: - | AG8: - | AH8: 1.34052 | AI8: 수익증권 | AJ8: AB미국그로스증권투자신탁(주식-재간접형)Ce-P2 | AK8: 6310605 | AL8: 2844.5 | AM8: 17950518 | AN8: 15337523 | AO8: 36715755 | AP8: 24659463 | AQ8: 0 | AR8: - | AS8: - | AT8: 0.17037 | AU8: 수익증권 | AV8: 한국투자연금베트남증권자투자신탁(주식혼합)C-Re | AW8: 10546825 | AX8: 1040.32 | AY8: 10972074 | AZ8: 10250000 | BA8: 10250000 | BB8: 0 | BC8: 0 | BD8: - | BE8: - | BF8: 0.07045 | BG8: 수익증권 | BH8: 우리하이플러스채권증권자투자신탁1호(채권)C-Pe | BI8: 25866799 | BJ8: 1044.09 | BK8: 27007269 | BL8: 25060000 | BM8: 25585000 | BN8: 525814 | BO8: 0 | BP8: - | BQ8: - | BR8: 0.0777 | BS8: 수익증권 | BT8: 한국투자글로벌AI&반도체TOP10증권자투자신탁UH(주식)C-Re | BU8: 7932805 | BV8: 2986.92 | BW8: 23694654 | BX8: 22780000 | BY8: 22780000 | BZ8: 0 | CA8: 0 | CB8: - | CC8: - | CD8: 0.04015 | CE8: ETF | CF8: WON 미국우주항공방산 | CG8: 228 | CH8: 27185 | CI8: 6198180 | CJ8: 6144600 | CK8: 0 | CL8: 0 | CM8: 0 | CN8: - | CO8: - | CP8: 0.00872 | CQ8: ETF | CR8: KODEX 로봇액티브 | CS8: 201 | CT8: 34405 | CU8: 6915405 | CV8: 7363635 | CW8: 0 | CX8: 0 | CY8: 0 | CZ8: - | DA8: - | DB8: -0.06087 | DC8: ETF | DD8: ACE 미국30년국채액티브(H) | DE8: 1410 | DF8: 7635 | DG8: 10765350 | DH8: 11611350 | DI8: 0 | DJ8: 0 | DK8: 0 | DL8: - | DM8: - | DN8: -0.07286 | DO8: 현금성자산(원화) | DP8: 자동운용상품(고유계정대) | DQ8: 0 | DR8: 0 | DS8: 513297 | DT8: 513297 | DU8: 0 | DV8: 0 | DW8: 0 | DX8: - | DY8: - | DZ8: 0
A9: =IF(B9>0,A8+1,"") | C9: =IF(B9>0,C8,"") | D9: {=IFERROR(INDEX(Data_Input!$1:$100, 10, MATCH(1, (Data_Input!$7:$7=$F$3) * (Data_Input!$8:$8=$B9), 0)), "")} | E9: {=IFERROR(INDEX(Data_Input!$1:$100, 9, MATCH(1, (Data_Input!$7:$7=$F$3) * (Data_Input!$8:$8=$B9), 0)),"")} | F9: {=IFERROR(INDEX(Data_Input!$A$1:$ZZ$502, MATCH("플랜번호", INDEX(Data_Input!$A$1:$ZZ$502, 0, MATCH(1, (Data_Input!$7:$7="IRP")*(Data_Input!$8:$8=$B9), 0)), 0) + 1, MATCH(1, (Data_Input!$7:$7=$F$3)*(Data_Input!$8:$8=$B9), 0)),"")} | G9: {=IFERROR(INDEX(Data_Input!$A$1:$ZZ$502, MATCH("플랜명", INDEX(Data_Input!$A$1:$ZZ$502, 0, MATCH(1, (Data_Input!$7:$7="IRP")*(Data_Input!$8:$8=$B9), 0)), 0) + 1, MATCH(1, (Data_Input!$7:$7=$F$3)*(Data_Input!$8:$8=$B9), 0)),"")} | H9: {=IFERROR(INDEX(Data_Input!$A$1:$ZZ$502, MATCH("평가금액", INDEX(Data_Input!$A$1:$ZZ$502, 0, MATCH(1, (Data_Input!$7:$7="IRP")*(Data_Input!$8:$8=$B9), 0)), 0) + 1, MATCH(1, (Data_Input!$7:$7=$F$3)*(Data_Input!$8:$8=$B9), 0)),"")} | I9: {=IFERROR(INDEX(Data_Input!$A$1:$ZZ$502, MATCH("평가손익", INDEX(Data_Input!$A$1:$ZZ$502, 0, MATCH(1, (Data_Input!$7:$7="IRP")*(Data_Input!$8:$8=$B9), 0)), 0) + 1, MATCH(1, (Data_Input!$7:$7=$F$3)*(Data_Input!$8:$8=$B9), 0)),"")} | J9: {=IFERROR(INDEX(Data_Input!$A$1:$ZZ$502, MATCH("누적수익률", INDEX(Data_Input!$A$1:$ZZ$502, 0, MATCH(1, (Data_Input!$7:$7="IRP")*(Data_Input!$8:$8=$B9), 0)), 0) + 1, MATCH(1, (Data_Input!$7:$7=$F$3)*(Data_Input!$8:$8=$B9), 0))/100,"")} | K9: {=IFERROR(_xlfn.LET( _xlpm.targetDate, B9, _xlpm.colIdx, MATCH(1, (Data_Input!$7:$7=$F$3) * (Data_Input!$8:$8=_xlpm.targetDate), 0), _xlpm.allData, INDEX(Data_Input!$1:$1002, 33, _xlpm.colIdx):INDEX(Data_Input!$1:$1002, 1000, _xlpm.colIdx), _xlpm.validData, _xlfn._xlws.FILTER(_xlpm.allData, _xlpm.allData <> ""), _xlpm.finalData, _xlfn.MAP(_xlfn.SEQUENCE(ROWS(_xlpm.validData)), _xlfn.LAMBDA(_xlpm.r, _xlfn.LET( _xlpm.curr, INDEX(_xlpm.validData, _xlpm.r), _xlpm.next, IF(_xlpm.r=ROWS(_xlpm.validData), "END", INDEX(_xlpm.validData, _xlpm.r+1)), IF(AND(ISNUMBER(_xlpm.curr), ISTEXT(_xlpm.next)), _xlpm.curr/100, _xlpm.curr) ) )), _xlfn.TOROW(_xlpm.finalData) ),"")}
A10: =IF(B10>0,A9+1,"") | C10: =IF(B10>0,C9,"") | D10: {=IFERROR(INDEX(Data_Input!$1:$100, 10, MATCH(1, (Data_Input!$7:$7=$F$3) * (Data_Input!$8:$8=$B10), 0)), "")} | E10: {=IFERROR(INDEX(Data_Input!$1:$100, 9, MATCH(1, (Data_Input!$7:$7=$F$3) * (Data_Input!$8:$8=$B10), 0)),"")} | F10: {=IFERROR(INDEX(Data_Input!$A$1:$ZZ$502, MATCH("플랜번호", INDEX(Data_Input!$A$1:$ZZ$502, 0, MATCH(1, (Data_Input!$7:$7="IRP")*(Data_Input!$8:$8=$B10), 0)), 0) + 1, MATCH(1, (Data_Input!$7:$7=$F$3)*(Data_Input!$8:$8=$B10), 0)),"")} | G10: {=IFERROR(INDEX(Data_Input!$A$1:$ZZ$502, MATCH("플랜명", INDEX(Data_Input!$A$1:$ZZ$502, 0, MATCH(1, (Data_Input!$7:$7="IRP")*(Data_Input!$8:$8=$B10), 0)), 0) + 1, MATCH(1, (Data_Input!$7:$7=$F$3)*(Data_Input!$8:$8=$B10), 0)),"")} | H10: {=IFERROR(INDEX(Data_Input!$A$1:$ZZ$502, MATCH("평가금액", INDEX(Data_Input!$A$1:$ZZ$502, 0, MATCH(1, (Data_Input!$7:$7="IRP")*(Data_Input!$8:$8=$B10), 0)), 0) + 1, MATCH(1, (Data_Input!$7:$7=$F$3)*(Data_Input!$8:$8=$B10), 0)),"")} | I10: {=IFERROR(INDEX(Data_Input!$A$1:$ZZ$502, MATCH("평가손익", INDEX(Data_Input!$A$1:$ZZ$502, 0, MATCH(1, (Data_Input!$7:$7="IRP")*(Data_Input!$8:$8=$B10), 0)), 0) + 1, MATCH(1, (Data_Input!$7:$7=$F$3)*(Data_Input!$8:$8=$B10), 0)),"")} | J10: {=IFERROR(INDEX(Data_Input!$A$1:$ZZ$502, MATCH("누적수익률", INDEX(Data_Input!$A$1:$ZZ$502, 0, MATCH(1, (Data_Input!$7:$7="IRP")*(Data_Input!$8:$8=$B10), 0)), 0) + 1, MATCH(1, (Data_Input!$7:$7=$F$3)*(Data_Input!$8:$8=$B10), 0))/100,"")} | K10: {=IFERROR(_xlfn.LET( _xlpm.targetDate, B10, _xlpm.colIdx, MATCH(1, (Data_Input!$7:$7=$F$3) * (Data_Input!$8:$8=_xlpm.targetDate), 0), _xlpm.allData, INDEX(Data_Input!$1:$1002, 33, _xlpm.colIdx):INDEX(Data_Input!$1:$1002, 1000, _xlpm.colIdx), _xlpm.validData, _xlfn._xlws.FILTER(_xlpm.allData, _xlpm.allData <> ""), _xlpm.finalData, _xlfn.MAP(_xlfn.SEQUENCE(ROWS(_xlpm.validData)), _xlfn.LAMBDA(_xlpm.r, _xlfn.LET( _xlpm.curr, INDEX(_xlpm.validData, _xlpm.r), _xlpm.next, IF(_xlpm.r=ROWS(_xlpm.validData), "END", INDEX(_xlpm.validData, _xlpm.r+1)), IF(AND(ISNUMBER(_xlpm.curr), ISTEXT(_xlpm.next)), _xlpm.curr/100, _xlpm.curr) ) )), _xlfn.TOROW(_xlpm.finalData) ),"")}
A11: =IF(B11>0,A10+1,"") | C11: =IF(B11>0,C10,"") | D11: {=IFERROR(INDEX(Data_Input!$1:$100, 10, MATCH(1, (Data_Input!$7:$7=$F$3) * (Data_Input!$8:$8=$B11), 0)), "")} | E11: {=IFERROR(INDEX(Data_Input!$1:$100, 9, MATCH(1, (Data_Input!$7:$7=$F$3) * (Data_Input!$8:$8=$B11), 0)),"")} | F11: {=IFERROR(INDEX(Data_Input!$A$1:$ZZ$502, MATCH("플랜번호", INDEX(Data_Input!$A$1:$ZZ$502, 0, MATCH(1, (Data_Input!$7:$7="IRP")*(Data_Input!$8:$8=$B11), 0)), 0) + 1, MATCH(1, (Data_Input!$7:$7=$F$3)*(Data_Input!$8:$8=$B11), 0)),"")} | G11: {=IFERROR(INDEX(Data_Input!$A$1:$ZZ$502, MATCH("플랜명", INDEX(Data_Input!$A$1:$ZZ$502, 0, MATCH(1, (Data_Input!$7:$7="IRP")*(Data_Input!$8:$8=$B11), 0)), 0) + 1, MATCH(1, (Data_Input!$7:$7=$F$3)*(Data_Input!$8:$8=$B11), 0)),"")} | H11: {=IFERROR(INDEX(Data_Input!$A$1:$ZZ$502, MATCH("평가금액", INDEX(Data_Input!$A$1:$ZZ$502, 0, MATCH(1, (Data_Input!$7:$7="IRP")*(Data_Input!$8:$8=$B11), 0)), 0) + 1, MATCH(1, (Data_Input!$7:$7=$F$3)*(Data_Input!$8:$8=$B11), 0)),"")} | I11: {=IFERROR(INDEX(Data_Input!$A$1:$ZZ$502, MATCH("평가손익", INDEX(Data_Input!$A$1:$ZZ$502, 0, MATCH(1, (Data_Input!$7:$7="IRP")*(Data_Input!$8:$8=$B11), 0)), 0) + 1, MATCH(1, (Data_Input!$7:$7=$F$3)*(Data_Input!$8:$8=$B11), 0)),"")} | J11: {=IFERROR(INDEX(Data_Input!$A$1:$ZZ$502, MATCH("누적수익률", INDEX(Data_Input!$A$1:$ZZ$502, 0, MATCH(1, (Data_Input!$7:$7="IRP")*(Data_Input!$8:$8=$B11), 0)), 0) + 1, MATCH(1, (Data_Input!$7:$7=$F$3)*(Data_Input!$8:$8=$B11), 0))/100,"")} | K11: {=IFERROR(_xlfn.LET( _xlpm.targetDate, B11, _xlpm.colIdx, MATCH(1, (Data_Input!$7:$7=$F$3) * (Data_Input!$8:$8=_xlpm.targetDate), 0), _xlpm.allData, INDEX(Data_Input!$1:$1002, 33, _xlpm.colIdx):INDEX(Data_Input!$1:$1002, 1000, _xlpm.colIdx), _xlpm.validData, _xlfn._xlws.FILTER(_xlpm.allData, _xlpm.allData <> ""), _xlpm.finalData, _xlfn.MAP(_xlfn.SEQUENCE(ROWS(_xlpm.validData)), _xlfn.LAMBDA(_xlpm.r, _xlfn.LET( _xlpm.curr, INDEX(_xlpm.validData, _xlpm.r), _xlpm.next, IF(_xlpm.r=ROWS(_xlpm.validData), "END", INDEX(_xlpm.validData, _xlpm.r+1)), IF(AND(ISNUMBER(_xlpm.curr), ISTEXT(_xlpm.next)), _xlpm.curr/100, _xlpm.curr) ) )), _xlfn.TOROW(_xlpm.finalData) ),"")}
